Workbook
Name ·······: Equipos!$A$2:$D$33
Name a: Administrador!#REF!
Name cmh: MUNDIAL!$CI$57
Name Nivel: Tabla3[NombreEquipo]
Name Nivell: Equipos!$C$2:$C$25
Name Nivell: Equipos!$C$2:$C$25
Name Nivell: Equipos!$C$2:$C$33
Name NombreEquipo: Equipos!$B$2:$B$33
Name OK: Equipos!$A$2:$A$33
Name Rank: Equipos!$D$2:$D$33

Sheet Inicio
B15: Esta versión es para un máximo de 5 participantes
F19: Foto: De Jcer80 - Trabajo propio, CC BY-SA 3.0, wikipedia
AGD57: {=IF(AND($CC$57:$CC$58=$CC$57,$CC$58<>$CC$59,$CC$59<>$CC$60,$CC$60<>$CC$61,$CC$61:$CC$62=$CC$61,$CE$57:$CE$58=$CE$57,$CE$61:$CE$62=$CE$61,$CF$57:$CF$58=$CF$57,$CF$61<>$CF$62,$CG$57:$CG$58=$CG$57),1,0)} -> 0 | AGE57: {=IF(AND($CC$57:$CC$58=$CC$57,$CC$58<>$CC$59,$CC$59<>$CC$60,$CC$60<>$CC$61,$CC$61:$CC$62=$CC$61,$CE$57:$CE$58=$CE$57,$CE$61:$CE$62=$CE$61,$CF$57<>$CF$58,$CF$61:$CF$62=$CF$61,$CG$61:$CG$62=$CG$61),1,0)} -> 0 | AGF57: {=IF(AND($CC$57:$CC$58=$CC$57,$CC$58<>$CC$59,$CC$59<>$CC$60,$CC$60<>$CC$61,$CC$61:$CC$62=$CC$61,$CE$57:$CE$58=$CE$57,$CE$61:$CE$62=$CE$61,$CF$57<>$CF$58,$CF$61<>$CF$62),1,0)} -> 0
CF58: 5 | AGD58: {=IF(AND($CC$57:$CC$58=$CC$58,$CC$58<>$CC$59,$CC$59<>$CC$60,$CC$60<>$CC$61,$CC$61:$CC$62=$CC$61,$CE$57:$CE$58=$CE$58,$CE$61:$CE$62=$CE$61,$CF$57:$CF$58=$CF$58,$CF$61<>$CF$62,$CG$57:$CG$58=$CG$58),1,0)} -> 0 | AGE58: {=IF(AND($CC$57:$CC$58=$CC$58,$CC$58<>$CC$59,$CC$59<>$CC$60,$CC$60<>$CC$61,$CC$61:$CC$62=$CC$61,$CE$57:$CE$58=$CE$58,$CE$61:$CE$62=$CE$61,$CF$57<>$CF$58,$CF$61:$CF$62=$CF$61,$CG$61:$CG$62=$CG$61),1,0)} -> 0 | AGF58: {=IF(AND($CC$57:$CC$58=$CC$58,$CC$58<>$CC$59,$CC$59<>$CC$60,$CC$60<>$CC$61,$CC$61:$CC$62=$CC$61,$CE$57:$CE$58=$CE$58,$CE$61:$CE$62=$CE$61,$CF$57<>$CF$58,$CF$61<>$CF$62),1,0)} -> 0
JZ59: {=IF(AND($CC$57:$CC$62=$CC$59,$CE$57:$CE$62=$CE$59,$CF$57:$CF$58=$CF$58,$CF$58<>$CF$59,$CF$59:$CF$62=$CF$59,$CG$57:$CG$58=$CG$58,$CG$59<>$CG$60,$CG$60:$CG$62=$CG$60),1,0)} -> 0 | AGD59: {=IF(AND($CC$57:$CC$58=$CC$58,$CC$58<>$CC$59,$CC$59<>$CC$60,$CC$60<>$CC$61,$CC$61:$CC$62=$CC$61,$CE$57:$CE$58=$CE$58,$CE$61:$CE$62=$CE$61,$CF$57:$CF$58=$CF$58,$CF$61<>$CF$62,$CG$57:$CG$58=$CG$58),1,0)} -> 0 | AGE59: {=IF(AND($CC$57:$CC$58=$CC$58,$CC$58<>$CC$59,$CC$59<>$CC$60,$CC$60<>$CC$61,$CC$61:$CC$62=$CC$61,$CE$57:$CE$58=$CE$58,$CE$61:$CE$62=$CE$61,$CF$57<>$CF$58,$CF$61:$CF$62=$CF$61,$CG$61:$CG$62=$CG$61),1,0)} -> 0 | AGF59: {=IF(AND($CC$57:$CC$58=$CC$58,$CC$58<>$CC$59,$CC$59<>$CC$60,$CC$60<>$CC$61,$CC$61:$CC$62=$CC$61,$CE$57:$CE$58=$CE$58,$CE$61:$CE$62=$CE$61,$CF$57<>$CF$58,$CF$61<>$CF$62),1,0)} -> 0
JZ60: {=IF(AND($CC$57:$CC$62=$CC$60,$CE$57:$CE$62=$CE$60,$CF$57:$CF$58=$CF$58,$CF$58<>$CF$59,$CF$59:$CF$62=$CF$60,$CG$57:$CG$58=$CG$58,$CG$59<>$CG$60,$CG$60:$CG$62=$CG$60),1,0)} -> 0 | AFZ60: {=IF(AND($CC$57:$CC$58=$CC$58,$CC$58<>$CC$59,$CC$59<>$CC$60,$CC$60:$CC$62=$CC$60,$CE$57:$CE$58=$CE$58,$CE$60:$CE$62=$CE$60,$CF$57<>$CF$58,$CF$60:$CF$62=$CF$60,$CG$60:$CG$62=$CG$60),1,0)} -> 0 | AGA60: {=IF(AND($CC$57:$CC$58=$CC$58,$CC$58<>$CC$59,$CC$59<>$CC$60,$CC$60:$CC$62=$CC$60,$CE$57:$CE$58=$CE$58,$CE$60:$CE$62=$CE$60,$CF$57<>$CF$58,$CF$60:$CF$62=$CF$60,$CG$60:$CG$62=$CG$60),1,0)} -> 0 | AGD60: {=IF(AND($CC$57:$CC$58=$CC$58,$CC$58<>$CC$59,$CC$59<>$CC$60,$CC$60<>$CC$61,$CC$61:$CC$62=$CC$61,$CE$57:$CE$58=$CE$58,$CE$61:$CE$62=$CE$61,$CF$57:$CF$58=$CF$58,$CF$61<>$CF$62,$CG$57:$CG$58=$CG$58),1,0)} -> 0 | AGE60: {=IF(AND($CC$57:$CC$58=$CC$58,$CC$58<>$CC$59,$CC$59<>$CC$60,$CC$60<>$CC$61,$CC$61:$CC$62=$CC$61,$CE$57:$CE$58=$CE$58,$CE$61:$CE$62=$CE$61,$CF$57<>$CF$58,$CF$61:$CF$62=$CF$61,$CG$61:$CG$62=$CG$61),1,0)} -> 0 | AGF60: {=IF(AND($CC$57:$CC$58=$CC$58,$CC$58<>$CC$59,$CC$59<>$CC$60,$CC$60<>$CC$61,$CC$61:$CC$62=$CC$61,$CE$57:$CE$58=$CE$58,$CE$61:$CE$62=$CE$61,$CF$57<>$CF$58,$CF$61<>$CF$62),1,0)} -> 0
JZ61: {=IF(AND($CC$57:$CC$62=$CC$61,$CE$57:$CE$62=$CE$61,$CF$57:$CF$58=$CF$58,$CF$58<>$CF$59,$CF$59:$CF$62=$CF$60,$CG$57:$CG$58=$CG$58,$CG$59<>$CG$60,$CG$60:$CG$62=$CG$61),1,0)} -> 0 | AFZ61: {=IF(AND($CC$57:$CC$58=$CC$58,$CC$58<>$CC$59,$CC$59<>$CC$60,$CC$60:$CC$62=$CC$61,$CE$57:$CE$58=$CE$58,$CE$60:$CE$62=$CE$61,$CF$57<>$CF$58,$CF$60:$CF$62=$CF$61,$CG$60:$CG$62=$CG$61),1,0)} -> 0 | AGA61: {=IF(AND($CC$57:$CC$58=$CC$58,$CC$58<>$CC$59,$CC$59<>$CC$60,$CC$60:$CC$62=$CC$61,$CE$57:$CE$58=$CE$58,$CE$60:$CE$62=$CE$61,$CF$57<>$CF$58,$CF$60:$CF$62=$CF$61,$CG$60:$CG$62=$CG$61),1,0)} -> 0 | AGD61: {=IF(AND($CC$57:$CC$58=$CC$58,$CC$58<>$CC$59,$CC$59<>$CC$60,$CC$60<>$CC$61,$CC$61:$CC$62=$CC$61,$CE$57:$CE$58=$CE$58,$CE$61:$CE$62=$CE$61,$CF$57:$CF$58=$CF$58,$CF$61<>$CF$62,$CG$57:$CG$58=$CG$58),1,0)} -> 0 | AGE61: {=IF(AND($CC$57:$CC$58=$CC$58,$CC$58<>$CC$59,$CC$59<>$CC$60,$CC$60<>$CC$61,$CC$61:$CC$62=$CC$61,$CE$57:$CE$58=$CE$58,$CE$61:$CE$62=$CE$61,$CF$57<>$CF$58,$CF$61:$CF$62=$CF$61,$CG$61:$CG$62=$CG$61),1,0)} -> 0 | AGF61: {=IF(AND($CC$57:$CC$58=$CC$58,$CC$58<>$CC$59,$CC$59<>$CC$60,$CC$60<>$CC$61,$CC$61:$CC$62=$CC$61,$CE$57:$CE$58=$CE$58,$CE$61:$CE$62=$CE$61,$CF$57<>$CF$58,$CF$61<>$CF$62),1,0)} -> 0
CF62: 1 | JZ62: {=IF(AND($CC$57:$CC$62=$CC$62,$CE$57:$CE$62=$CE$62,$CF$57:$CF$58=$CF$58,$CF$58<>$CF$59,$CF$59:$CF$62=$CF$60,$CG$57:$CG$58=$CG$58,$CG$59<>$CG$60,$CG$60:$CG$62=$CG$62),1,0)} -> 0 | AFZ62: {=IF(AND($CC$57:$CC$58=$CC$58,$CC$58<>$CC$59,$CC$59<>$CC$60,$CC$60:$CC$62=$CC$62,$CE$57:$CE$58=$CE$58,$CE$60:$CE$62=$CE$62,$CF$57<>$CF$58,$CF$60:$CF$62=$CF$62,$CG$60:$CG$62=$CG$62),1,0)} -> 0 | AGA62: {=IF(AND($CC$57:$CC$58=$CC$58,$CC$58<>$CC$59,$CC$59<>$CC$60,$CC$60:$CC$62=$CC$62,$CE$57:$CE$58=$CE$58,$CE$60:$CE$62=$CE$62,$CF$57<>$CF$58,$CF$60:$CF$62=$CF$62,$CG$60:$CG$62=$CG$62),1,0)} -> 0 | AGD62: {=IF(AND($CC$57:$CC$58=$CC$58,$CC$58<>$CC$59,$CC$59<>$CC$60,$CC$60<>$CC$61,$CC$61:$CC$62=$CC$62,$CE$57:$CE$58=$CE$58,$CE$61:$CE$62=$CE$62,$CF$57:$CF$58=$CF$58,$CF$61<>$CF$62,$CG$57:$CG$58=$CG$58),1,0)} -> 0 | AGE62: {=IF(AND($CC$57:$CC$58=$CC$58,$CC$58<>$CC$59,$CC$59<>$CC$60,$CC$60<>$CC$61,$CC$61:$CC$62=$CC$62,$CE$57:$CE$58=$CE$58,$CE$61:$CE$62=$CE$62,$CF$57<>$CF$58,$CF$61:$CF$62=$CF$62,$CG$61:$CG$62=$CG$62),1,0)} -> 0 | AGF62: {=IF(AND($CC$57:$CC$58=$CC$58,$CC$58<>$CC$59,$CC$59<>$CC$60,$CC$60<>$CC$61,$CC$61:$CC$62=$CC$62,$CE$57:$CE$58=$CE$58,$CE$61:$CE$62=$CE$62,$CF$57<>$CF$58,$CF$61<>$CF$62),1,0)} -> 0 | AGX62: {=IF(AND($CC$57<>$CC$58,$CC$58:$CC$62=$CC$62,$CE$58:$CE$62=$CE$62,$CF$58<>$CF$59,$CF$59<>$CF$60,$CF$60<>$CF$61,$CF$61:$CF$62=$CF$62,$CG$61:$CG$62=$CG$62),1,0)} -> 0 | AGY62: {=IF(AND($CC$57<>$CC$58,$CC$58:$CC$62=$CC$62,$CE$58:$CE$62=$CE$62,$CF$58<>$CF$59,$CF$59<>$CF$60,$CF$60<>$CF$61,$CF$61<>$CF$62),1,0)} -> 0

Sheet MUNDIAL
E1: Selecciona Horario: | G1: Catar | I1: Rellenar los cuadros grises
G2: =IFERROR(VLOOKUP(G1,Horarios!L4:M60,2,0),10) -> 9 | AH2: AUXILIARES | AV2: TOPIC | AW2: VALUE | CT2: no
F3: Fecha | G3: Hora | H3: Jor. | I3: Casa | K3: Gol | L3: Gol | N3: Fuera | AV3: SIN EMPEZAR | AW3: =AW4*2 -> 2222000000 | CL3: 1 | CM3: 12 | CN3: 18 | CO3: 19 | CP3: 13 | CQ3: 20 | CR3: 21 | CS3: 22 | CT3: 3 | CU3: 2 | CV3: 14 | CW3: 17 | CX3: 16 | CY3: 15 | CZ3: 4 | DA3: 5 | DB3: 10 | DC3: 8 | DD3: 6 | DE3: 11 | DF3: 7 | DG3: 9 | EC3: OP1 | ED3: OP2 | EE3: OP3 | EF3: OP4 | EG3: OP5 | EH3: OP6 | EI3: OP7 | EJ3: OP8 | EK3: OP9 | EL3: OP10 | MEZ3: matejero
A4: NombreEquipo | B4: A | C4: =COUNTIF(Equipos!$C$2:$C$33,MUNDIAL!B4) -> 4 | E4: A | F4: =Horarios!C4 -> 44886.792 | G4: =Horarios!C4 -> 44886.792 | H4: J1 | I4: =A7 -> Senegal | J4: =VLOOKUP(I4,Equipos!$H$2:$I$33,2,0) -> 🇸🇳 | K4: 0 | L4: 2 | M4: =VLOOKUP(N4,Equipos!$H$2:$I$33,2,0) -> 🇳🇱 | N4: =A8 -> Paises Bajos | O4: =IF(NOT(OR(ISBLANK(K4),ISBLANK(L4))),1,0) -> 1 | Q4: =CONCATENATE("Grupo"," ",B4) -> Grupo A | AB4: ¡EMPATE! Puedes seleccionar el orden de los empatados. | AH4: =CONCATENATE("Auxiliar - ",Q4) -> Auxiliar - Grupo A | AU4: NR | AV4: PUNTOS General | AW4: =AW6*1111 -> 1111000000 | AY4: =CONCATENATE(Q4," - GOLAVERAGE") -> Grupo A - GOLAVERAGE | BB4: Goles - Partidos Cruzados | BH4: Diferencia de Goles - Partidos Cruzados | BN4: Puntos - Partidos Cruzados | CI4: Valor | CK4: Sum | CL4: =SUM(CL6:CL9) -> 0 | CM4: =SUM(CM6:CM9) -> 0 | CN4: =SUM(CN6:CN9) -> 0 | CO4: =SUM(CO6:CO9) -> 2 | CP4: =SUM(CP6:CP9) -> 0 | CQ4: =SUM(CQ6:CQ9) -> 2 | CR4: =SUM(CR6:CR9) -> 2 | CS4: =SUM(CS6:CS9) -> 4 | ... DG4: =SUM(DG6:DG9) -> 0 | EC4: 1234 | ED4: 123 | EE4: 12 | EF4: 234 | EG4: 34 | EH4: 23 | EI4: 1 | EJ4: 2 | EK4: 3 | EL4: 4
A5: {=IF(ROWS(A$5:A5)<=$C$4,INDEX(INDIRECT(A$4),SMALL(IF(Nivell=$B$4,ROW(Nivell)-ROW(Equipos!$C$2)+1),ROWS(B$4:B4))),"")} -> Catar | F5: =Horarios!C5 -> 44885.792 | G5: =Horarios!C5 -> 44885.792 | H5: J1 | I5: =A5 -> Catar | J5: =VLOOKUP(I5,Equipos!$H$2:$I$33,2,0) -> 🇶🇦 | K5: 0 | L5: 2 | M5: =VLOOKUP(N5,Equipos!$H$2:$I$33,2,0) -> 🇪🇨 | N5: =A6 -> Ecuador | O5: =IF(NOT(OR(ISBLANK(K5),ISBLANK(L5))),1,0) -> 1 | Q5: Pos | R5: Selección | S5: Pts | T5: J | U5: G | V5: E | W5: P | X5: GF | Y5: GC | Z5: DG | AA5: =COUNTIF(AA6:AA9,"<100") -> 0 | AG5: NR | AH5: Puesto | AI5: Equipo | AJ5: Ptos | AK5: J | AL5: G | AM5: E | AN5: P | AO5: GF | AP5: GC | AQ5: Dif | AR5: Rank | AS5: Puesto | AV5: DG X | AW5: =AW6*5 -> 5000000 | AY5: Equipo | AZ5: NEquipEqual | BA5: PUNTOS | BB5: Ranking Inv | BC5: Entre Iguales | BD5: =AY6 -> Catar | BE5: =AY7 -> Ecuador | BF5: =AY8 -> Senegal | BG5: =AY9 -> Paises Bajos | BH5: Ranking Inv | BI5: Entre Iguales | BJ5: =BD5 -> Catar | BK5: =BE5 -> Ecuador | BL5: =BF5 -> Senegal | BM5: =BG5 -> Paises Bajos | BN5: Ranking Inv | BO5: Entre Iguales | BP5: =BD5 -> Catar | BQ5: =BE5 -> Ecuador | BR5: =BF5 -> Senegal | BS5: =BG5 -> Paises Bajos | BV5: Inicio | BW5: =AR | BX5: 1R | CB5: Equipo | CC5: Ptos | CD5: Signo | CE5: Dif | CF5: Gf | CK5: Com | CL5: COM_1 | CM5: COM_2 | CN5: COM_3 | CO5: COM_4 | CP5: COM_5 | CQ5: COM_6 | CR5: COM_7 | CS5: COM_8 | CT5: COM_3 | CU5: COM_3 | CV5: COM_4 | CW5: COM_7 | CX5: COM_6 | CY5: COM_6 | CZ5: COM_5 | DA5: COM_2 | DB5: COM_7 | DC5: COM_6 | DD5: COM_4 | DE5: COM_7 | DF5: COM_4 | DG5: COM_6 | EC5: 1 | ED5: 1 | EE5: 1 | EF5: 2 | EG5: 3 | EH5: 2 | EI5: 1 | EJ5: 2 | EK5: 3 | EL5: 4
A6: {=IF(ROWS(A$5:A6)<=$C$4,INDEX(INDIRECT(A$4),SMALL(IF(Nivell=$B$4,ROW(Nivell)-ROW(Equipos!$C$2)+1),ROWS(B$4:B5))),"")} -> Ecuador | F6: =Horarios!C6 -> 44890.667 | G6: =Horarios!C6 -> 44890.667 | H6: J2 | I6: =A5 -> Catar | J6: =VLOOKUP(I6,Equipos!$H$2:$I$33,2,0) -> 🇶🇦 | K6: 1 | L6: 2 | M6: =VLOOKUP(N6,Equipos!$H$2:$I$33,2,0) -> 🇸🇳 | N6: =A7 -> Senegal | O6: =IF(NOT(OR(ISBLANK(K6),ISBLANK(L6))),1,0) -> 1 | Q6: 1 | R6: =VLOOKUP(Q6,$AG$6:$AI$9,3,0) -> Paises Bajos | S6: =VLOOKUP(R6,$AI$6:$AR$9,2,FALSE) -> 7 | T6: =VLOOKUP($R6,$AI$6:$AR$9,3,FALSE) -> 3 | U6: =VLOOKUP($R6,$AI$6:$AR$9,4,FALSE) -> 2 | V6: =VLOOKUP($R6,$AI$6:$AR$9,5,FALSE) -> 1 | W6: =VLOOKUP($R6,$AI$6:$AR$9,6,FALSE) -> 0 | X6: =VLOOKUP($R6,$AI$6:$AR$9,7,FALSE) -> 5 | Y6: =VLOOKUP($R6,$AI$6:$AR$9,8,FALSE) -> 1 | Z6: =VLOOKUP($R6,$AI$6:$AR$9,9,FALSE) -> 4 | AA6: =IF(SUM($AK$6:$AK$9)=12,MIN(ABS(BY5-BY6),ABS(BY6-BY7)),100) -> 1.132e+09 | AB6: =IF(AND(AA6>=0,AA6<90),VLOOKUP(Q6,$BU$6:$BV$9,2,0),"") | AF6: =VLOOKUP($R6,$AI$6:$AR$9,10,FALSE) -> 7.8022105e+09 | AG6: =RANK(AU6,$AU$6:$AU$9) -> 4 | AH6: =RANK(AR6,$AR$6:$AR$9) -> 4 | AI6: =A5 -> Catar | AJ6: =AL6*3+AM6*1+AN6*0 -> 0 | AK6: =COUNTIFS($I$4:$I$65,AI6,$K$4:$K$65,"<>",$L$4:$L$65,"<>")+COUNTIFS($N$4:$N$65,AI6,$L$4:$L$65,"<>",$K$4:$K$65,"<>") -> 3 | AL6: {=SUM(($I$4:$I$65=AI6)*($K$4:$K$65<>"")*($L$4:$L$65<>"")*($K$4:$K$65>$L$4:$L$65),($N$4:$N$65=AI6)*($K$4:$K$65<>"")*($L$4:$L$65<>"")*($K$4:$K$65<$L$4:$L$65))} -> 0 | AM6: {=SUM(($I$4:$I$65=AI6)*($K$4:$K$65<>"")*($L$4:$L$65<>"")*($K$4:$K$65=$L$4:$L$65),($N$4:$N$65=AI6)*($K$4:$K$65<>"")*($L$4:$L$65<>"")*($K$4:$K$65=$L$4:$L$65))} -> 0 | AN6: {=SUM(($I$4:$I$65=AI6)*($L$4:$L$65<>"")*($K$4:$K$65<>"")*($K$4:$K$65<$L$4:$L$65),($K$4:$K$65<>"")*($N$4:$N$65=AI6)*($L$4:$L$65<>"")*($K$4:$K$65>$L$4:$L$65))} -> 3 | AO6: {=SUMIFS($K$4:$K$65,$I$4:$I$65,AI6,$K$4:$K$65,"<>",$L$4:$L$65,"<>")+SUMIFS($L$4:$L$65,$N$4:$N$65,AI6,$K$4:$K$65,"<>",$L$4:$L$65,"<>")} -> 1 | AP6: {=SUMIFS($K$4:$K$65,$N$4:$N$65,AI6,$K$4:$K$65,"<>",$L$4:$L$65,"<>")+SUMIFS($L$4:$L$65,$I$4:$I$65,AI6,$K$4:$K$65,"<>",$L$4:$L$65,"<>")} -> 6 | AQ6: =AO6-AP6 -> -5 | AR6: =IF(AK6=0,-($AW$11*VLOOKUP(AI6,Tabla3[[NombreEquipo]:[Rank]],3,FALSE)),AJ6*$AW$4+AQ6*$AW$5+AO6*$AW$6+BA6-($AW$11*VLOOKUP(AI6,Tabla3[[NombreEquipo]:[Rank]],3,FALSE)/100)) -> -23789500 | AS6: =AH6 -> 4 | AU6: =IFERROR(AR6-VLOOKUP(AI6,$AB$6:$AC$9,2,0),AR6) -> -23789500 | AV6: G X | AW6: =AW7*5 -> 1000000 | AY6: =AI6 -> Catar | AZ6: =COUNTIF(AJ6:AJ9,AJ6) -> 1 | BA6: =(BB6*$AW$9)+(BH6*$AW$8)+(BN6*$AW$7) -> 210500 | BB6: =RANK(BC6,BC6:BC9,1) -> 1 | BC6: =SUM(IF(AND(AJ6=AJ7,AQ6=AQ7,AO6=AO7),BE6,0),IF(AND(AJ6=AJ8,AQ6=AQ8,AO6=AO8),BF6,0),IF(AND(AJ6=AJ9,AQ6=AQ9,AO6=AO9),BG6,0)) -> 0 | BD6: 0 | BE6: {=SUMIFS($K$4:$K$9,$I$4:$I$9,$AY6,$K$4:$K$9,"<>",$L$4:$L$9,"<>",$N$4:$N$9,BE5)+SUMIFS($L$4:$L$9,$I$4:$I$9,BE5,$K$4:$K$9,"<>",$L$4:$L$9,"<>",$N$4:$N$9,$AY6)} -> 0 | BF6: {=SUMIFS($K$4:$K$9,$I$4:$I$9,$AY6,$K$4:$K$9,"<>",$L$4:$L$9,"<>",$N$4:$N$9,BF5)+SUMIFS($L$4:$L$9,$I$4:$I$9,BF5,$K$4:$K$9,"<>",$L$4:$L$9,"<>",$N$4:$N$9,$AY6)} -> 1 | BG6: {=SUMIFS($K$4:$K$9,$I$4:$I$9,$AY6,$K$4:$K$9,"<>",$L$4:$L$9,"<>",$N$4:$N$9,BG5)+SUMIFS($L$4:$L$9,$I$4:$I$9,BG5,$K$4:$K$9,"<>",$L$4:$L$9,"<>",$N$4:$N$9,$AY6)} -> 0 | BH6: =RANK(BI6,BI6:BI9,1) -> 1 | BI6: =SUM(IF(AND(AJ6=AJ7,AQ6=AQ7,AO6=AO7),BK6,0),IF(AND(AJ6=AJ8,AQ6=AQ8,AO6=AO8),BL6,0),IF(AND(AJ6=AJ9,AQ6=AQ9,AO6=AO9),BM6,0)) -> 0 | BJ6: 0 | BK6: =BE6-BD7 -> -2 | BL6: =BF6-BD8 -> -1 | BM6: =BG6-BD9 -> -2 | BN6: =RANK(BO6,BO6:BO9,1) -> 1 | BO6: =SUM(IF(AND(AJ6=AJ7,AQ6=AQ7,AO6=AO7),BQ6,0),IF(AND(AJ6=AJ8,AQ6=AQ8,AO6=AO8),BR6,0),IF(AND(AJ6=AJ9,AQ6=AQ9,AO6=AO9),BS6,0)) -> 0 | BP6: 0 | BQ6: {=SUM((I$4:I$49=AY6)*(N$4:N$49=BQ5)*(K$4:K$49<>"")*(L$4:L$49<>"")*(K$4:K$49>L$4:L$49)*3,(N$4:N$49=AY6)*(I$4:I$49=BQ5)*(K$4:K$49<>"")*(L$4:L$49<>"")*(K$4:K$49=L$4:L$49)*1,(N$4:N$49=AY6)*(I$4:I$49=BQ5)*(K$4:K$49<>"")*(L$4:L$49<>"")*(K$4:K$49<L$4:L$49)*3,(I$4:I$49=AY6)*(N$4:N$49=BQ5)*(K$4:K$49<>"")*(L$4:L$49<>"")*(K$4:K$49=L$4:L$49)*1)} -> 0 | BR6: {=SUM((I$4:I$49=AY6)*(N$4:N$49=BR5)*(K$4:K$49<>"")*(L$4:L$49<>"")*(K$4:K$49>L$4:L$49)*3,(N$4:N$49=AY6)*(I$4:I$49=BR5)*(K$4:K$49<>"")*(L$4:L$49<>"")*(K$4:K$49=L$4:L$49)*1,(N$4:N$49=AY6)*(I$4:I$49=BR5)*(K$4:K$49<>"")*(L$4:L$49<>"")*(K$4:K$49<L$4:L$49)*3,(I$4:I$49=AY6)*(N$4:N$49=BR5)*(K$4:K$49<>"")*(L$4:L$49<>"")*(K$4:K$49=L$4:L$49)*1)} -> 0 | BS6: {=SUM((I$4:I$49=AY6)*(N$4:N$49=BS5)*(K$4:K$49<>"")*(L$4:L$49<>"")*(K$4:K$49>L$4:L$49)*3,(N$4:N$49=AY6)*(I$4:I$49=BS5)*(K$4:K$49<>"")*(L$4:L$49<>"")*(K$4:K$49=L$4:L$49)*1,(N$4:N$49=AY6)*(I$4:I$49=BS5)*(K$4:K$49<>"")*(L$4:L$49<>"")*(K$4:K$49<L$4:L$49)*3,(I$4:I$49=AY6)*(N$4:N$49=BS5)*(K$4:K$49<>"")*(L$4:L$49<>"")*(K$4:K$49=L$4:L$49)*1)} -> 0 | BT6: 1 | BU6: =RANK(BW6,$BW$6:$BW$9) -> 4 | BV6: =A5 -> Catar | BW6: =AR6 -> -23789500 | BX6: =VLOOKUP(Q6,$AH$6:$AI$9,2,0) -> Paises Bajos | BY6: =VLOOKUP($BX6,$AI$6:$AR$9,10,FALSE) -> 7.8022105e+09 | CA6: 1 | CB6: =VLOOKUP(CA6,$AH$6:$AI$9,2,0) -> Paises Bajos | CC6: =VLOOKUP(CB6,$AI$6:$AR$9,2,FALSE) -> 7 | CD6: =IF(SUM($AK$6:$AK$9)=12,MIN(ABS(BY5-BY6),ABS(BY6-BY7)),100) -> 1.132e+09 | CE6: =VLOOKUP($CB6,$AI$6:$AR$9,9,FALSE) -> 4 | CF6: =VLOOKUP($CB6,$AI$6:$AR$9,7,FALSE) -> 5 | CH6: {=IF($CI$6=$CL$5,$EC$5:$EC$8,IF($CI$6=$CM$5,$ED$5:$ED$7,IF(OR($CI$6=$CN$5,$CI$6=$CO$5),$EE$5:$EE$6,$EI$5)))} -> 1 | CI6: =IFERROR(HLOOKUP(4,CL4:DI5,2,0),CS5) -> COM_8 | CK6: 1 | CL6: {=IF(AND($CC$6:$CC$9=$CC$6,$CD$6:$CD$9<90,$AQ$6:$AQ$9=$AQ$6,$CF$6:$CF$9=$CF$6),1,0)} -> 0 | CM6: {=IF(AND($CC$6:$CC$8=$CC$6,$CD$6:$CD$8<90,$CC$6<>$CC$9),1,0)} -> 0 | CN6: {=IF(AND($CC$6:$CC$7=$CC$6,$CD$6:$CD$7<90,$CC$6<>$CC$8),1,0)} -> 0 | CO6: {=IF(AND($CC$6:$CC$7=$CC$6,$CD$6:$CD$7<90,$CC$6<>$CC$8),1,0)} -> 0 | CP6: {=IF(AND($CC$7:$CC$9=$CC$7,$CD$7:$CD$9<90,$CC$6<>$CC$7),1,0)} -> 0 | CQ6: {=IF(AND($CC$6<>$CC$7,$CC$6<>$CC$9),1,0)} -> 1 | CR6: {=IF(AND($CC$6<>$CC$7,$CC$6<>$CC$9),1,0)} -> 1 | CS6: {=IF(AND($CC$6<>$CC$7,$CC$6<>$CC$9),1,0)} -> 1 | CT6: {=IF(AND($CC$6:$CC$9=$CC$6,$CD$6:$CD$9<90,$CE$6:$CE$7=$CE$6,$CE$6<>$CE$8),1,0)} -> 0 | CU6: {=IF(AND($CC$6:$CC$9=$CC$6,$CD$6:$CD$9<90,$CE$6:$CE$9=$CE$6,$CF$6=$CF$7,$CF$6<>$CF$8),1,0)} -> 0 | CV6: {=IF(AND($CC$6:$CC$8=$CC$6,$CD$6:$CD$7<90,$CD$8>90),1,0)} -> 0 | CW6: {=IF(AND($CC$6<>$CC$7,$CC$6<>$CC$8),1,0)} -> 1 | CX6: {=IF(AND($CC$6<>$CC$7,$CC$6<>$CC$8),1,0)} -> 1 | CY6: {=IF(AND($CC$6<>$CC$9,$CC$6:$CC$8=$CC$6,$CD$6>90,$CD$7:$CD$8<90),1,0)} -> 0 | CZ6: {=IF(AND($CC$6:$CC$9=$CC$6,$CD$7:$CD$9<90,$CD$6<>$CD$7),1,0)} -> 0 | DA6: {=IF(AND($CC$6:$CC$9=$CC$6,$CD$6:$CD$8<90,$CD$6<>$CD$9),1,0)} -> 0 | DB6: {=IF(AND($CC$6:$CC$9=$CC$6,$CD$6:$CD$7>90,$CD$8:$CD$9<90,$CE$6:$CE$9=$CE$6,$CF$6>$CF$7,$CF$6>$CF$8,$CF$6>$CF$9),1,0)} -> 0 | DC6: {=IF(AND($CC$6:$CC$9=$CC$6,$CD$6>90,$CD$7:$CD$8<90,$CD$9>90,$CE$6:$CE$9=$CE$6,$CF$6>$CF$7,$CF$6>$CF$8,$CF$6>$CF$9),1,0)} -> 0 | DD6: {=IF(AND($CC$6:$CC$9=$CC$6,$CD$6:$CD$7<90,$CD$8:$CD$9>90,$CE$6:$CE$9=$CE$6,$CF$6=$CF$7,$CF$6>$CF$8,$CF$6>$CF$9),1,0)} -> 0 | DE6: {=IF(AND($CC$6:$CC$9=$CC$6,$CD$6:$CD$7>90,$CD$8:$CD$9<90,$CE$6:$CE$9=$CE$6,$CF$6>$CF$7,$CF$7:$CF$9=$CF$7),1,0)} -> 0 | DF6: {=IF(AND($CC$6:$CC$9=$CC$6,$CD$6:$CD$7<90,$CD$8:$CD$9>90,$CE$6:$CE$9=$CE$6,$CF$6:$CF$8=$CF$6,$CF$6>$CF$9),1,0)} -> 0 | DG6: {=IF(AND($CC$6:$CC$9=$CC$6,$CD$6>90,$CD$9>90,$CD$7:$CD$8<90,$CE$6:$CE$9=$CE$6,$CF$6>$CF$7:$CF$9),1,0)} -> 0 | EC6: 2 | ED6: 2 | EE6: 2 | EF6: 3 | EG6: 4 | EH6: 3
A7: {=IF(ROWS(A$5:A7)<=$C$4,INDEX(INDIRECT(A$4),SMALL(IF(Nivell=$B$4,ROW(Nivell)-ROW(Equipos!$C$2)+1),ROWS(B$4:B6))),"")} -> Senegal | F7: =Horarios!C7 -> 44890.792 | G7: =Horarios!C7 -> 44890.792 | H7: J2 | I7: =A8 -> Paises Bajos | J7: =VLOOKUP(I7,Equipos!$H$2:$I$33,2,0) -> 🇳🇱 | K7: 1 | L7: 1 | M7: =VLOOKUP(N7,Equipos!$H$2:$I$33,2,0) -> 🇪🇨 | N7: =A6 -> Ecuador | O7: =IF(NOT(OR(ISBLANK(K7),ISBLANK(L7))),1,0) -> 1 | Q7: 2 | R7: =VLOOKUP(Q7,$AG$6:$AI$9,3,0) -> Senegal | S7: =VLOOKUP(R7,$AI$6:$AR$9,2,FALSE) -> 6 | T7: =VLOOKUP($R7,$AI$6:$AR$9,3,FALSE) -> 3 | U7: =VLOOKUP($R7,$AI$6:$AR$9,4,FALSE) -> 2 | V7: =VLOOKUP($R7,$AI$6:$AR$9,5,FALSE) -> 0 | W7: =VLOOKUP($R7,$AI$6:$AR$9,6,FALSE) -> 1 | X7: =VLOOKUP($R7,$AI$6:$AR$9,7,FALSE) -> 4 | Y7: =VLOOKUP($R7,$AI$6:$AR$9,8,FALSE) -> 4 | Z7: =VLOOKUP($R7,$AI$6:$AR$9,9,FALSE) -> 0 | AA7: =IF(SUM($AK$6:$AK$9)=12,MIN(ABS(BY6-BY7),ABS(BY7-BY8)),100) -> 1.132e+09 | AB7: =IF(AND(AA7>=0,AA7<90),VLOOKUP(Q7,$BU$6:$BV$9,2,0),"") | AF7: =VLOOKUP($R7,$AI$6:$AR$9,10,FALSE) -> 6.6702105e+09 | AG7: =RANK(AU7,$AU$6:$AU$9) -> 3 | AH7: =RANK(AR7,$AR$6:$AR$9) -> 3 | AI7: =A6 -> Ecuador | AJ7: =AL7*3+AM7*1+AN7*0 -> 4 | AK7: =COUNTIFS($I$4:$I$65,AI7,$K$4:$K$65,"<>",$L$4:$L$65,"<>")+COUNTIFS($N$4:$N$65,AI7,$L$4:$L$65,"<>",$K$4:$K$65,"<>") -> 3 | AL7: {=SUM(($I$4:$I$65=AI7)*($K$4:$K$65<>"")*($L$4:$L$65<>"")*($K$4:$K$65>$L$4:$L$65),($N$4:$N$65=AI7)*($K$4:$K$65<>"")*($L$4:$L$65<>"")*($K$4:$K$65<$L$4:$L$65))} -> 1 | AM7: {=SUM(($I$4:$I$65=AI7)*($K$4:$K$65<>"")*($L$4:$L$65<>"")*($K$4:$K$65=$L$4:$L$65),($N$4:$N$65=AI7)*($K$4:$K$65<>"")*($L$4:$L$65<>"")*($K$4:$K$65=$L$4:$L$65))} -> 1 | AN7: {=SUM(($I$4:$I$65=AI7)*($L$4:$L$65<>"")*($K$4:$K$65<>"")*($K$4:$K$65<$L$4:$L$65),($K$4:$K$65<>"")*($N$4:$N$65=AI7)*($L$4:$L$65<>"")*($K$4:$K$65>$L$4:$L$65))} -> 1 | AO7: {=SUMIFS($K$4:$K$65,$I$4:$I$65,AI7,$K$4:$K$65,"<>",$L$4:$L$65,"<>")+SUMIFS($L$4:$L$65,$N$4:$N$65,AI7,$K$4:$K$65,"<>",$L$4:$L$65,"<>")} -> 4 | AP7: {=SUMIFS($K$4:$K$65,$N$4:$N$65,AI7,$K$4:$K$65,"<>",$L$4:$L$65,"<>")+SUMIFS($L$4:$L$65,$I$4:$I$65,AI7,$K$4:$K$65,"<>",$L$4:$L$65,"<>")} -> 3 | AQ7: =AO7-AP7 -> 1 | AR7: =IF(AK7=0,-($AW$11*VLOOKUP(AI7,Tabla3[[NombreEquipo]:[Rank]],3,FALSE)),AJ7*$AW$4+AQ7*$AW$5+AO7*$AW$6+BA7-($AW$11*VLOOKUP(AI7,Tabla3[[NombreEquipo]:[Rank]],3,FALSE)/100)) -> 4.4532105e+09 | AS7: =AH7 -> 3 | AU7: =IFERROR(AR7-VLOOKUP(AI7,$AB$6:$AC$9,2,0),AR7) -> 4.4532105e+09 | AV7: P Part | AW7: =AW8*20 -> 200000 | AY7: =AI7 -> Ecuador | AZ7: =COUNTIF(AJ6:AJ9,AJ7) -> 1 | BA7: =(BB7*$AW$9)+(BH7*$AW$8)+(BN7*$AW$7) -> 210500 | BB7: =RANK(BC7,BC6:BC9,1) -> 1 | BC7: =SUM(IF(AND(AJ7=AJ8,AQ7=AQ8,AO7=AO8),BF7,0),IF(AND(AJ7=AJ9,AQ7=AQ9,AO7=AO9),BG7,0),IF(AND(AJ7=AJ6,AQ7=AQ6,AO7=AO6),BD7,0)) -> 0 | BD7: {=SUMIFS($K$4:$K$9,$I$4:$I$9,$AY7,$K$4:$K$9,"<>",$L$4:$L$9,"<>",$N$4:$N$9,BD5)+SUMIFS($L$4:$L$9,$I$4:$I$9,BD5,$K$4:$K$9,"<>",$L$4:$L$9,"<>",$N$4:$N$9,$AY7)} -> 2 | BE7: 0 | BF7: {=SUMIFS($K$4:$K$9,$I$4:$I$9,$AY7,$K$4:$K$9,"<>",$L$4:$L$9,"<>",$N$4:$N$9,BF5)+SUMIFS($L$4:$L$9,$I$4:$I$9,BF5,$K$4:$K$9,"<>",$L$4:$L$9,"<>",$N$4:$N$9,$AY7)} -> 1 | BG7: {=SUMIFS($K$4:$K$9,$I$4:$I$9,$AY7,$K$4:$K$9,"<>",$L$4:$L$9,"<>",$N$4:$N$9,BG5)+SUMIFS($L$4:$L$9,$I$4:$I$9,BG5,$K$4:$K$9,"<>",$L$4:$L$9,"<>",$N$4:$N$9,$AY7)} -> 1 | BH7: =RANK(BI7,BI6:BI9,1) -> 1 | BI7: =SUM(IF(AND(AJ7=AJ8,AQ7=AQ8,AO7=AO8),BL7,0),IF(AND(AJ7=AJ9,AQ7=AQ9,AO7=AO9),BM7,0),IF(AND(AJ7=AJ6,AQ7=AQ6,AO7=AO6),BJ7,0)) -> 0 | BJ7: =BD7-BE6 -> 2 | BK7: 0 | BL7: =BF7-BE8 -> -1 | BM7: =BG7-BE9 -> 0 | BN7: =RANK(BO7,BO6:BO9,1) -> 1 | BO7: =SUM(IF(AND(AJ7=AJ8,AQ7=AQ8,AO7=AO8),BR7,0),IF(AND(AJ7=AJ9,AQ7=AQ9,AO7=AO9),BS7,0),IF(AND(AJ7=AJ6,AQ7=AQ6,AO7=AO6),BP7,0)) -> 0 | BP7: {=SUM((I$4:I$49=AY7)*(N$4:N$49=BP5)*(K$4:K$49<>"")*(L$4:L$49<>"")*(K$4:K$49>L$4:L$49)*3,(N$4:N$49=AY7)*(I$4:I$49=BP5)*(K$4:K$49<>"")*(L$4:L$49<>"")*(K$4:K$49=L$4:L$49)*1,(N$4:N$49=AY7)*(I$4:I$49=BP5)*(K$4:K$49<>"")*(L$4:L$49<>"")*(K$4:K$49<L$4:L$49)*3,(I$4:I$49=AY7)*(N$4:N$49=BP5)*(K$4:K$49<>"")*(L$4:L$49<>"")*(K$4:K$49=L$4:L$49)*1)} -> 3 | BQ7: 0 | BR7: {=SUM((I$4:I$49=AY7)*(N$4:N$49=BR5)*(K$4:K$49<>"")*(L$4:L$49<>"")*(K$4:K$49>L$4:L$49)*3,(N$4:N$49=AY7)*(I$4:I$49=BR5)*(K$4:K$49<>"")*(L$4:L$49<>"")*(K$4:K$49=L$4:L$49)*1,(N$4:N$49=AY7)*(I$4:I$49=BR5)*(K$4:K$49<>"")*(L$4:L$49<>"")*(K$4:K$49<L$4:L$49)*3,(I$4:I$49=AY7)*(N$4:N$49=BR5)*(K$4:K$49<>"")*(L$4:L$49<>"")*(K$4:K$49=L$4:L$49)*1)} -> 0 | BS7: {=SUM((I$4:I$49=AY7)*(N$4:N$49=BS5)*(K$4:K$49<>"")*(L$4:L$49<>"")*(K$4:K$49>L$4:L$49)*3,(N$4:N$49=AY7)*(I$4:I$49=BS5)*(K$4:K$49<>"")*(L$4:L$49<>"")*(K$4:K$49=L$4:L$49)*1,(N$4:N$49=AY7)*(I$4:I$49=BS5)*(K$4:K$49<>"")*(L$4:L$49<>"")*(K$4:K$49<L$4:L$49)*3,(I$4:I$49=AY7)*(N$4:N$49=BS5)*(K$4:K$49<>"")*(L$4:L$49<>"")*(K$4:K$49=L$4:L$49)*1)} -> 1 | BT7: 2 | BU7: =RANK(BW7,$BW$6:$BW$9) -> 3 | BV7: =A6 -> Ecuador | BW7: =AR7 -> 4.4532105e+09 | BX7: =VLOOKUP(Q7,$AH$6:$AI$9,2,0) -> Senegal | BY7: =VLOOKUP($BX7,$AI$6:$AR$9,10,FALSE) -> 6.6702105e+09 | CA7: 2 | CB7: =VLOOKUP(CA7,$AH$6:$AI$9,2,0) -> Senegal | CC7: =VLOOKUP(CB7,$AI$6:$AR$9,2,FALSE) -> 6 | CD7: =IF(SUM($AK$6:$AK$9)=12,MIN(ABS(BY6-BY7),ABS(BY7-BY8)),100) -> 1.132e+09 | CE7: =VLOOKUP($CB7,$AI$6:$AR$9,9,FALSE) -> 0 | CF7: =VLOOKUP($CB7,$AI$6:$AR$9,7,FALSE) -> 4 | CH7: {=IF($CI$6=$CL$5,$EC$5:$EC$8,IF($CI$6=$CM$5,$ED$5:$ED$7,IF(OR($CI$6=$CN$5,$CI$6=$CO$5),$EE$5:$EE$6,IF($CI$6=$CP$5,$EF$5:$EF$7,(IF($CI$6=$CQ$5,$EH$5:$EH$6,$EJ$5))))))} -> 2 | CK7: 2 | CL7: {=IF(AND($CC$6:$CC$9=$CC$7,$CD$6:$CD$9<90,$AQ$6:$AQ$9=$AQ$7,$CF$6:$CF$9=$CF$7),1,0)} -> 0 | CM7: {=IF(AND($CC$6:$CC$8=$CC$7,$CD$6:$CD$8<90,$CC$7<>$CC$9),1,0)} -> 0 | CN7: {=IF(AND($CC$6:$CC$7=$CC$6,$CD$6:$CD$7<90,$CC$6<>$CC$8),1,0)} -> 0 | CO7: {=IF(AND($CC$6:$CC$7=$CC$6,$CD$6:$CD$7<90,$CC$6<>$CC$8),1,0)} -> 0 | CP7: {=IF(AND($CC$7:$CC$9=$CC$7,$CD$7:$CD$9<90,$CC$6<>$CC$7),1,0)} -> 0 | CQ7: {=IF(AND($CC$7:$CC$8=$CC$7,$CD$7:$CD$8<90,$CC$7<>$CC$6,$CC$7<>$CC$9),1,0)} -> 0 | CR7: {=IF(AND($CC$7<>$CC$6,$CC$7<>$CC$8),1,0)} -> 1 | CS7: {=IF(AND($CC$7<>$CC$6,$CC$7<>$CC$8),1,0)} -> 1 | CT7: {=IF(AND($CC$6:$CC$9=$CC$6,$CD$6:$CD$9<90,$CE$6:$CE$7=$CE$6,$CE$7<>$CE$8),1,0)} -> 0 | CU7: {=IF(AND($CC$6:$CC$9=$CC$6,$CD$6:$CD$9<90,$CE$6:$CE$9=$CE$6,$CF$6=$CF$7,$CF$7<>$CF$8),1,0)} -> 0 | CV7: {=IF(AND($CC$6:$CC$8=$CC$7,$CD$6:$CD$7<90,$CD$8>90),1,0)} -> 0 | CW7: {=IF(AND($CC$7<>$CC$6,$CC$7:$CC$9=$CC$7,$CD$7>90,$CD$8:$CD$9<90),1,0)} -> 0 | CX7: {=IF(AND($CC$7<>$CC$6,$CC$7:$CC$9=$CC$7,$CD$9>90,$CD$7:$CD$8<90),1,0)} -> 0 | CY7: {=IF(AND($CC$7<>$CC$9,$CC$6:$CC$8=$CC$7,$CD$6>90,$CD$7:$CD$8<90),1,0)} -> 0 | CZ7: {=IF(AND($CC$6:$CC$9=$CC$7,$CD$7:$CD$9<90,$CD$6<>$CD$7),1,0)} -> 0 | DA7: {=IF(AND($CC$6:$CC$9=$CC$7,$CD$6:$CD$8<90,$CD$7<>$CD$9),1,0)} -> 0 | DB7: {=IF(AND($CC$6:$CC$9=$CC$7,$CD$6:$CD$7>90,$CD$8:$CD$9<90,$CE$6:$CE$9=$CE$7,$CF$6>$CF$7,$CF$7>$CF$8,$CF$7>$CF$9),1,0)} -> 0 | DC7: {=IF(AND($CC$6:$CC$9=$CC$7,$CD$6>90,$CD$7:$CD$8<90,$CD$9>90,$CE$6:$CE$9=$CE$7,$CF$6>$CF$7,$CF$7=$CF$8,$CF$7>$CF$9),1,0)} -> 0 | DD7: {=IF(AND($CC$6:$CC$9=$CC$7,$CD$6:$CD$7<90,$CD$8:$CD$9>90,$CE$6:$CE$9=$CE$7,$CF$6=$CF$7,$CF$7>$CF$8,$CF$7>$CF$9),1,0)} -> 0 | DE7: {=IF(AND($CC$6:$CC$9=$CC$7,$CD$6:$CD$7>90,$CD$8:$CD$9<90,$CE$6:$CE$9=$CE$7,$CF$6>$CF$7,$CF$7:$CF$9=$CF$7),1,0)} -> 0 | DF7: {=IF(AND($CC$6:$CC$9=$CC$7,$CD$6:$CD$7<90,$CD$8:$CD$9>90,$CE$6:$CE$9=$CE$7,$CF$6:$CF$8=$CF$7,$CF$7>$CF$9),1,0)} -> 0 | DG7: {=IF(AND($CC$6:$CC$9=$CC$7,$CD$6>90,$CD$9>90,$CD$7:$CD$8<90,$CE$6:$CE$9=$CE$7,$CF$6>$CF$7:$CF$9,$CF$7:$CF$9=$CF$7),1,0)} -> 0 | EC7: 3 | ED7: 3 | EF7: 4
A8: {=IF(ROWS(A$5:A8)<=$C$4,INDEX(INDIRECT(A$4),SMALL(IF(Nivell=$B$4,ROW(Nivell)-ROW(Equipos!$C$2)+1),ROWS(B$4:B7))),"")} -> Paises Bajos | F8: =Horarios!C8 -> 44894.75 | G8: =Horarios!C8 -> 44894.75 | H8: J3 | I8: =A6 -> Ecuador | J8: =VLOOKUP(I8,Equipos!$H$2:$I$33,2,0) -> 🇪🇨 | K8: 1 | L8: 2 | M8: =VLOOKUP(N8,Equipos!$H$2:$I$33,2,0) -> 🇸🇳 | N8: =A7 -> Senegal | O8: =IF(NOT(OR(ISBLANK(K8),ISBLANK(L8))),1,0) -> 1 | Q8: 3 | R8: =VLOOKUP(Q8,$AG$6:$AI$9,3,0) -> Ecuador | S8: =VLOOKUP(R8,$AI$6:$AR$9,2,FALSE) -> 4 | T8: =VLOOKUP($R8,$AI$6:$AR$9,3,FALSE) -> 3 | U8: =VLOOKUP($R8,$AI$6:$AR$9,4,FALSE) -> 1 | V8: =VLOOKUP($R8,$AI$6:$AR$9,5,FALSE) -> 1 | W8: =VLOOKUP($R8,$AI$6:$AR$9,6,FALSE) -> 1 | X8: =VLOOKUP($R8,$AI$6:$AR$9,7,FALSE) -> 4 | Y8: =VLOOKUP($R8,$AI$6:$AR$9,8,FALSE) -> 3 | Z8: =VLOOKUP($R8,$AI$6:$AR$9,9,FALSE) -> 1 | AA8: =IF(SUM($AK$6:$AK$9)=12,MIN(ABS(BY7-BY8),ABS(BY8-BY9)),100) -> 2.217e+09 | AB8: =IF(AND(AA8>=0,AA8<90),VLOOKUP(Q8,$BU$6:$BV$9,2,0),"") | AF8: =VLOOKUP($R8,$AI$6:$AR$9,10,FALSE) -> 4.4532105e+09 | AG8: =RANK(AU8,$AU$6:$AU$9) -> 2 | AH8: =RANK(AR8,$AR$6:$AR$9) -> 2 | AI8: =A7 -> Senegal | AJ8: =AL8*3+AM8*1+AN8*0 -> 6 | AK8: =COUNTIFS($I$4:$I$65,AI8,$K$4:$K$65,"<>",$L$4:$L$65,"<>")+COUNTIFS($N$4:$N$65,AI8,$L$4:$L$65,"<>",$K$4:$K$65,"<>") -> 3 | AL8: {=SUM(($I$4:$I$65=AI8)*($K$4:$K$65<>"")*($L$4:$L$65<>"")*($K$4:$K$65>$L$4:$L$65),($N$4:$N$65=AI8)*($K$4:$K$65<>"")*($L$4:$L$65<>"")*($K$4:$K$65<$L$4:$L$65))} -> 2 | AM8: {=SUM(($I$4:$I$65=AI8)*($K$4:$K$65<>"")*($L$4:$L$65<>"")*($K$4:$K$65=$L$4:$L$65),($N$4:$N$65=AI8)*($K$4:$K$65<>"")*($L$4:$L$65<>"")*($K$4:$K$65=$L$4:$L$65))} -> 0 | AN8: {=SUM(($I$4:$I$65=AI8)*($L$4:$L$65<>"")*($K$4:$K$65<>"")*($K$4:$K$65<$L$4:$L$65),($K$4:$K$65<>"")*($N$4:$N$65=AI8)*($L$4:$L$65<>"")*($K$4:$K$65>$L$4:$L$65))} -> 1 | AO8: {=SUMIFS($K$4:$K$65,$I$4:$I$65,AI8,$K$4:$K$65,"<>",$L$4:$L$65,"<>")+SUMIFS($L$4:$L$65,$N$4:$N$65,AI8,$K$4:$K$65,"<>",$L$4:$L$65,"<>")} -> 4 | AP8: {=SUMIFS($K$4:$K$65,$N$4:$N$65,AI8,$K$4:$K$65,"<>",$L$4:$L$65,"<>")+SUMIFS($L$4:$L$65,$I$4:$I$65,AI8,$K$4:$K$65,"<>",$L$4:$L$65,"<>")} -> 4 | AQ8: =AO8-AP8 -> 0 | AR8: =IF(AK8=0,-($AW$11*VLOOKUP(AI8,Tabla3[[NombreEquipo]:[Rank]],3,FALSE)),AJ8*$AW$4+AQ8*$AW$5+AO8*$AW$6+BA8-($AW$11*VLOOKUP(AI8,Tabla3[[NombreEquipo]:[Rank]],3,FALSE)/100)) -> 6.6702105e+09 | AS8: =AH8 -> 2 | AU8: =IFERROR(AR8-VLOOKUP(AI8,$AB$6:$AC$9,2,0),AR8) -> 6.6702105e+09 | AV8: DG part | AW8: =AW9*20 -> 10000 | AY8: =AI8 -> Senegal | AZ8: =COUNTIF(AJ6:AJ9,AJ8) -> 1 | BA8: =(BB8*$AW$9)+(BH8*$AW$8)+(BN8*$AW$7) -> 210500 | BB8: =RANK(BC8,BC6:BC9,1) -> 1 | BC8: =SUM(IF(AND(AJ8=AJ9,AQ8=AQ9,AO8=AO9),BG8,0),IF(AND(AJ8=AJ6,AQ8=AQ6,AO8=AO6),BD8,0),IF(AND(AJ8=AJ7,AQ8=AQ7,AO8=AO7),BE8,0)) -> 0 | BD8: {=SUMIFS($K$4:$K$9,$I$4:$I$9,$AY8,$K$4:$K$9,"<>",$L$4:$L$9,"<>",$N$4:$N$9,BD5)+SUMIFS($L$4:$L$9,$I$4:$I$9,BD5,$K$4:$K$9,"<>",$L$4:$L$9,"<>",$N$4:$N$9,$AY8)} -> 2 | BE8: {=SUMIFS($K$4:$K$9,$I$4:$I$9,$AY8,$K$4:$K$9,"<>",$L$4:$L$9,"<>",$N$4:$N$9,BE5)+SUMIFS($L$4:$L$9,$I$4:$I$9,BE5,$K$4:$K$9,"<>",$L$4:$L$9,"<>",$N$4:$N$9,$AY8)} -> 2 | BF8: 0 | BG8: {=SUMIFS($K$4:$K$9,$I$4:$I$9,$AY8,$K$4:$K$9,"<>",$L$4:$L$9,"<>",$N$4:$N$9,BG5)+SUMIFS($L$4:$L$9,$I$4:$I$9,BG5,$K$4:$K$9,"<>",$L$4:$L$9,"<>",$N$4:$N$9,$AY8)} -> 0 | BH8: =RANK(BI8,BI6:BI9,1) -> 1 | BI8: =SUM(IF(AND(AJ8=AJ9,AQ8=AQ9,AO8=AO9),BM8,0),IF(AND(AJ8=AJ6,AQ8=AQ6,AO8=AO6),BJ8,0),IF(AND(AJ8=AJ7,AQ8=AQ7,AO8=AO7),BK8,0)) -> 0 | BJ8: =BD8-BF6 -> 1 | BK8: =BE8-BF7 -> 1 | BL8: 0 | BM8: =BG8-BF9 -> -2 | BN8: =RANK(BO8,BO6:BO9,1) -> 1 | BO8: =SUM(IF(AND(AJ8=AJ9,AQ8=AQ9,AO8=AO9),BS8,0),IF(AND(AJ8=AJ6,AQ8=AQ6,AO8=AO6),BP8,0),IF(AND(AJ8=AJ7,AQ8=AQ7,AO8=AO7),BQ8,0)) -> 0 | BP8: {=SUM((I$4:I$49=AY8)*(N$4:N$49=BP5)*(K$4:K$49<>"")*(L$4:L$49<>"")*(K$4:K$49>L$4:L$49)*3,(N$4:N$49=AY8)*(I$4:I$49=BP5)*(K$4:K$49<>"")*(L$4:L$49<>"")*(K$4:K$49=L$4:L$49)*1,(N$4:N$49=AY8)*(I$4:I$49=BP5)*(K$4:K$49<>"")*(L$4:L$49<>"")*(K$4:K$49<L$4:L$49)*3,(I$4:I$49=AY8)*(N$4:N$49=BP5)*(K$4:K$49<>"")*(L$4:L$49<>"")*(K$4:K$49=L$4:L$49)*1)} -> 3 | BQ8: {=SUM((I$4:I$49=AY8)*(N$4:N$49=BQ5)*(K$4:K$49<>"")*(L$4:L$49<>"")*(K$4:K$49>L$4:L$49)*3,(N$4:N$49=AY8)*(I$4:I$49=BQ5)*(K$4:K$49<>"")*(L$4:L$49<>"")*(K$4:K$49=L$4:L$49)*1,(N$4:N$49=AY8)*(I$4:I$49=BQ5)*(K$4:K$49<>"")*(L$4:L$49<>"")*(K$4:K$49<L$4:L$49)*3,(I$4:I$49=AY8)*(N$4:N$49=BQ5)*(K$4:K$49<>"")*(L$4:L$49<>"")*(K$4:K$49=L$4:L$49)*1)} -> 3 | BR8: 0 | BS8: {=SUM((I$4:I$49=AY8)*(N$4:N$49=BS5)*(K$4:K$49<>"")*(L$4:L$49<>"")*(K$4:K$49>L$4:L$49)*3,(N$4:N$49=AY8)*(I$4:I$49=BS5)*(K$4:K$49<>"")*(L$4:L$49<>"")*(K$4:K$49=L$4:L$49)*1,(N$4:N$49=AY8)*(I$4:I$49=BS5)*(K$4:K$49<>"")*(L$4:L$49<>"")*(K$4:K$49<L$4:L$49)*3,(I$4:I$49=AY8)*(N$4:N$49=BS5)*(K$4:K$49<>"")*(L$4:L$49<>"")*(K$4:K$49=L$4:L$49)*1)} -> 0 | BT8: 3 | BU8: =RANK(BW8,$BW$6:$BW$9) -> 2 | BV8: =A7 -> Senegal | BW8: =AR8 -> 6.6702105e+09 | BX8: =VLOOKUP(Q8,$AH$6:$AI$9,2,0) -> Ecuador | BY8: =VLOOKUP($BX8,$AI$6:$AR$9,10,FALSE) -> 4.4532105e+09 | CA8: 3 | CB8: =VLOOKUP(CA8,$AH$6:$AI$9,2,0) -> Ecuador | CC8: =VLOOKUP(CB8,$AI$6:$AR$9,2,FALSE) -> 4 | CD8: =IF(SUM($AK$6:$AK$9)=12,MIN(ABS(BY7-BY8),ABS(BY8-BY9)),100) -> 2.217e+09 | CE8: =VLOOKUP($CB8,$AI$6:$AR$9,9,FALSE) -> 1 | CF8: =VLOOKUP($CB8,$AI$6:$AR$9,7,FALSE) -> 4 | CH8: {=IF($CI$6=$CL$5,$EC$5:$EC$8,IF($CI$6=$CM$5,$ED$5:$ED$7,IF(OR($CI$6=$CN$5,$CI$6=$CR$5),$EG$5:$EG$6,IF($CI$6=$CP$5,$EF$5:$EF$7,(IF($CI$6=$CQ$5,$EH$5:$EH$6,$EK$5))))))} -> 3 | CK8: 3 | CL8: {=IF(AND($CC$6:$CC$9=$CC$8,$CD$6:$CD$9<90,$AQ$6:$AQ$9=$AQ$8,$CF$6:$CF$9=$CF$8),1,0)} -> 0 | CM8: {=IF(AND($CC$6:$CC$8=$CC$8,$CD$6:$CD$8<90,$CC$8<>$CC$9),1,0)} -> 0 | CN8: {=IF(AND($CC$8:$CC$9=$CC$8,$CD$8:$CD$9<90,$CC$8<>$CC$7),1,0)} -> 0 | CO8: {=IF(OR(AND($CC$8<>$CC$7,$CC$8<>$CC$9),AND($CC$8<>$CC$7,$CC$8=$CC$9,$CD$8>90,$CD$9>90)),1,0)} -> 1 | CP8: {=IF(AND($CC$7:$CC$9=$CC$7,$CD$7:$CD$9<90,$CC$6<>$CC$8),1,0)} -> 0 | CQ8: {=IF(AND($CC$7:$CC$8=$CC$8,$CD$7:$CD$8<90,$CC$8<>$CC$6,$CC$8<>$CC$9),1,0)} -> 0 | CR8: {=IF(AND($CC$8:$CC$9=$CC$8,$CD$8:$CD$9<90,$CC$8<>$CC$7),1,0)} -> 0 | CS8: {=IF(AND($CC$8<>$CC$7,$CC$8<>$CC$9),1,0)} -> 1 | CT8: {=IF(AND($CC$6:$CC$9=$CC$6,$CD$6:$CD$9<90,$CE$8:$CE$9=$CE$8,$CE$7<>$CE$8),1,0)} -> 0 | CU8: {=IF(AND($CC$6:$CC$9=$CC$6,$CD$6:$CD$9<90,$CE$6:$CE$9=$CE$6,$CF$8=$CF$9,$CF$7<>$CF$8),1,0)} -> 0 | CV8: {=IF(AND($CC$6:$CC$8=$CC$8,$CD$6:$CD$7<90,$CD$8>90),1,0)} -> 0 | CW8: {=IF(AND($CC$7<>$CC$6,$CC$7:$CC$9=$CC$8,$CD$7>90,$CD$8:$CD$9<90),1,0)} -> 0 | CX8: {=IF(AND($CC$7<>$CC$6,$CC$7:$CC$9=$CC$7,$CD$9>90,$CD$7:$CD$8<90),1,0)} -> 0 | CY8: {=IF(AND($CC$8<>$CC$9,$CC$6:$CC$8=$CC$8,$CD$6>90,$CD$7:$CD$8<90),1,0)} -> 0 | CZ8: {=IF(AND($CC$6:$CC$9=$CC$7,$CD$7:$CD$9<90,$CD$6<>$CD$8),1,0)} -> 0 | DA8: {=IF(AND($CC$6:$CC$9=$CC$8,$CD$6:$CD$8<90,$CD$8<>$CD$9),1,0)} -> 0 | DB8: {=IF(AND($CC$6:$CC$9=$CC$8,$CD$6:$CD$7>90,$CD$8:$CD$9<90,$CE$6:$CE$9=$CE$8,$CF$6>$CF$7,$CF$7>$CF$8,$CF$8=$CF$9),1,0)} -> 0 | DC8: {=IF(AND($CC$6:$CC$9=$CC$8,$CD$6>90,$CD$7:$CD$8<90,$CD$9>90,$CE$6:$CE$9=$CE$8,$CF$6>$CF$7,$CF$7=$CF$8,$CF$8>$CF$9),1,0)} -> 0 | DD8: {=IF(AND($CC$6:$CC$9=$CC$8,$CD$6:$CD$7<90,$CD$8:$CD$9>90,$CE$6:$CE$9=$CE$8,$CF$6=$CF$7,$CF$7>$CF$8,$CF$8>$CF$9),1,0)} -> 0 | DE8: {=IF(AND($CC$6:$CC$9=$CC$8,$CD$6:$CD$7>90,$CD$8:$CD$9<90,$CE$6:$CE$9=$CE$7,$CF$6>$CF$8,$CF$7:$CF$9=$CF$8),1,0)} -> 0 | DF8: {=IF(AND($CC$6:$CC$9=$CC$8,$CD$6:$CD$7<90,$CD$8:$CD$9>90,$CE$6:$CE$9=$CE$8,$CF$6:$CF$8=$CF$8,$CF$8>$CF$9),1,0)} -> 0 | DG8: {=IF(AND($CC$6:$CC$9=$CC$8,$CD$6>90,$CD$9>90,$CD$7:$CD$8<90,$CE$6:$CE$9=$CE$8,$CF$6>$CF$7:$CF$9,$CF$7:$CF$9=$CF$8),1,0)} -> 0 | EC8: 4
F9: =Horarios!C9 -> 44894.75 | G9: =Horarios!C9 -> 44894.75 | H9: J3 | I9: =A8 -> Paises Bajos | J9: =VLOOKUP(I9,Equipos!$H$2:$I$33,2,0) -> 🇳🇱 | K9: 2 | L9: 0 | M9: =VLOOKUP(N9,Equipos!$H$2:$I$33,2,0) -> 🇶🇦 | N9: =A5 -> Catar | O9: =IF(NOT(OR(ISBLANK(K9),ISBLANK(L9))),1,0) -> 1 | Q9: 4 | R9: =VLOOKUP(Q9,$AG$6:$AI$9,3,0) -> Catar | S9: =VLOOKUP(R9,$AI$6:$AR$9,2,FALSE) -> 0 | T9: =VLOOKUP($R9,$AI$6:$AR$9,3,FALSE) -> 3 | U9: =VLOOKUP($R9,$AI$6:$AR$9,4,FALSE) -> 0 | V9: =VLOOKUP($R9,$AI$6:$AR$9,5,FALSE) -> 0 | W9: =VLOOKUP($R9,$AI$6:$AR$9,6,FALSE) -> 3 | X9: =VLOOKUP($R9,$AI$6:$AR$9,7,FALSE) -> 1 | Y9: =VLOOKUP($R9,$AI$6:$AR$9,8,FALSE) -> 6 | Z9: =VLOOKUP($R9,$AI$6:$AR$9,9,FALSE) -> -5 | AA9: =IF(SUM($AK$6:$AK$9)=12,MIN(ABS(BY8-BY9),ABS(BY9-BY10)),100) -> 23789500 | AB9: =IF(AND(AA9>=0,AA9<90),VLOOKUP(Q9,$BU$6:$BV$9,2,0),"") | AF9: =VLOOKUP($R9,$AI$6:$AR$9,10,FALSE) -> -23789500 | AG9: =RANK(AU9,$AU$6:$AU$9) -> 1 | AH9: =RANK(AR9,$AR$6:$AR$9) -> 1 | AI9: =A8 -> Paises Bajos | AJ9: =AL9*3+AM9*1+AN9*0 -> 7 | AK9: =COUNTIFS($I$4:$I$65,AI9,$K$4:$K$65,"<>",$L$4:$L$65,"<>")+COUNTIFS($N$4:$N$65,AI9,$L$4:$L$65,"<>",$K$4:$K$65,"<>") -> 3 | AL9: {=SUM(($I$4:$I$65=AI9)*($K$4:$K$65<>"")*($L$4:$L$65<>"")*($K$4:$K$65>$L$4:$L$65),($N$4:$N$65=AI9)*($K$4:$K$65<>"")*($L$4:$L$65<>"")*($K$4:$K$65<$L$4:$L$65))} -> 2 | AM9: {=SUM(($I$4:$I$65=AI9)*($K$4:$K$65<>"")*($L$4:$L$65<>"")*($K$4:$K$65=$L$4:$L$65),($N$4:$N$65=AI9)*($K$4:$K$65<>"")*($L$4:$L$65<>"")*($K$4:$K$65=$L$4:$L$65))} -> 1 | AN9: {=SUM(($I$4:$I$65=AI9)*($L$4:$L$65<>"")*($K$4:$K$65<>"")*($K$4:$K$65<$L$4:$L$65),($K$4:$K$65<>"")*($N$4:$N$65=AI9)*($L$4:$L$65<>"")*($K$4:$K$65>$L$4:$L$65))} -> 0 | AO9: {=SUMIFS($K$4:$K$65,$I$4:$I$65,AI9,$K$4:$K$65,"<>",$L$4:$L$65,"<>")+SUMIFS($L$4:$L$65,$N$4:$N$65,AI9,$K$4:$K$65,"<>",$L$4:$L$65,"<>")} -> 5 | AP9: {=SUMIFS($K$4:$K$65,$N$4:$N$65,AI9,$K$4:$K$65,"<>",$L$4:$L$65,"<>")+SUMIFS($L$4:$L$65,$I$4:$I$65,AI9,$K$4:$K$65,"<>",$L$4:$L$65,"<>")} -> 1 | AQ9: =AO9-AP9 -> 4 | AR9: =IF(AK9=0,-($AW$11*VLOOKUP(AI9,Tabla3[[NombreEquipo]:[Rank]],3,FALSE)),AJ9*$AW$4+AQ9*$AW$5+AO9*$AW$6+BA9-($AW$11*VLOOKUP(AI9,Tabla3[[NombreEquipo]:[Rank]],3,FALSE)/100)) -> 7.8022105e+09 | AS9: =AH9 -> 1 | AU9: =IFERROR(AR9-VLOOKUP(AI9,$AB$6:$AC$9,2,0),AR9) -> 7.8022105e+09 | AV9: G part | AW9: =AW10*5 -> 500 | AY9: =AI9 -> Paises Bajos | AZ9: =COUNTIF(AJ6:AJ9,AJ9) -> 1 | BA9: =(BB9*$AW$9)+(BH9*$AW$8)+(BN9*$AW$7) -> 210500 | BB9: =RANK(BC9,BC6:BC9,1) -> 1 | BC9: =SUM(IF(AND(AJ9=AJ6,AQ9=AQ6,AO9=AO6),BD9,0),IF(AND(AJ9=AJ7,AQ9=AQ7,AO9=AO7),BE9,0),IF(AND(AJ9=AJ8,AQ9=AQ8,AO9=AO8),BF9,0)) -> 0 | BD9: {=SUMIFS($K$4:$K$9,$I$4:$I$9,$AY9,$K$4:$K$9,"<>",$L$4:$L$9,"<>",$N$4:$N$9,BD5)+SUMIFS($L$4:$L$9,$I$4:$I$9,BD5,$K$4:$K$9,"<>",$L$4:$L$9,"<>",$N$4:$N$9,$AY9)} -> 2 | BE9: {=SUMIFS($K$4:$K$9,$I$4:$I$9,$AY9,$K$4:$K$9,"<>",$L$4:$L$9,"<>",$N$4:$N$9,BE5)+SUMIFS($L$4:$L$9,$I$4:$I$9,BE5,$K$4:$K$9,"<>",$L$4:$L$9,"<>",$N$4:$N$9,$AY9)} -> 1 | BF9: {=SUMIFS($K$4:$K$9,$I$4:$I$9,$AY9,$K$4:$K$9,"<>",$L$4:$L$9,"<>",$N$4:$N$9,BF5)+SUMIFS($L$4:$L$9,$I$4:$I$9,BF5,$K$4:$K$9,"<>",$L$4:$L$9,"<>",$N$4:$N$9,$AY9)} -> 2 | BG9: 0 | BH9: =RANK(BI9,BI6:BI9,1) -> 1 | BI9: =SUM(IF(AND(AJ9=AJ6,AQ9=AQ6,AO9=AO6),BJ9,0),IF(AND(AJ9=AJ7,AQ9=AQ7,AO9=AO7),BK9,0),IF(AND(AJ9=AJ8,AQ9=AQ8,AO9=AO8),BL9,0)) -> 0 | BJ9: =BD9-BG6 -> 2 | BK9: =BE9-BG7 -> 0 | BL9: =BF9-BG8 -> 2 | BM9: 0 | BN9: =RANK(BO9,BO6:BO9,1) -> 1 | BO9: =SUM(IF(AND(AJ9=AJ6,AQ9=AQ6,AO9=AO6),BP9,0),IF(AND(AJ9=AJ7,AQ9=AQ7,AO9=AO7),BQ9,0),IF(AND(AJ9=AJ8,AQ9=AQ8,AO9=AO8),BR9,0)) -> 0 | BP9: {=SUM((I$4:I$49=AY9)*(N$4:N$49=BP5)*(K$4:K$49<>"")*(L$4:L$49<>"")*(K$4:K$49>L$4:L$49)*3,(N$4:N$49=AY9)*(I$4:I$49=BP5)*(K$4:K$49<>"")*(L$4:L$49<>"")*(K$4:K$49=L$4:L$49)*1,(N$4:N$49=AY9)*(I$4:I$49=BP5)*(K$4:K$49<>"")*(L$4:L$49<>"")*(K$4:K$49<L$4:L$49)*3,(I$4:I$49=AY9)*(N$4:N$49=BP5)*(K$4:K$49<>"")*(L$4:L$49<>"")*(K$4:K$49=L$4:L$49)*1)} -> 3 | BQ9: {=SUM((I$4:I$49=AY9)*(N$4:N$49=BQ5)*(K$4:K$49<>"")*(L$4:L$49<>"")*(K$4:K$49>L$4:L$49)*3,(N$4:N$49=AY9)*(I$4:I$49=BQ5)*(K$4:K$49<>"")*(L$4:L$49<>"")*(K$4:K$49=L$4:L$49)*1,(N$4:N$49=AY9)*(I$4:I$49=BQ5)*(K$4:K$49<>"")*(L$4:L$49<>"")*(K$4:K$49<L$4:L$49)*3,(I$4:I$49=AY9)*(N$4:N$49=BQ5)*(K$4:K$49<>"")*(L$4:L$49<>"")*(K$4:K$49=L$4:L$49)*1)} -> 1 | BR9: {=SUM((I$4:I$49=AY9)*(N$4:N$49=BR5)*(K$4:K$49<>"")*(L$4:L$49<>"")*(K$4:K$49>L$4:L$49)*3,(N$4:N$49=AY9)*(I$4:I$49=BR5)*(K$4:K$49<>"")*(L$4:L$49<>"")*(K$4:K$49=L$4:L$49)*1,(N$4:N$49=AY9)*(I$4:I$49=BR5)*(K$4:K$49<>"")*(L$4:L$49<>"")*(K$4:K$49<L$4:L$49)*3,(I$4:I$49=AY9)*(N$4:N$49=BR5)*(K$4:K$49<>"")*(L$4:L$49<>"")*(K$4:K$49=L$4:L$49)*1)} -> 3 | BS9: 0 | BT9: 4 | BU9: =RANK(BW9,$BW$6:$BW$9) -> 1 | BV9: =A8 -> Paises Bajos | BW9: =AR9 -> 7.8022105e+09 | BX9: =VLOOKUP(Q9,$AH$6:$AI$9,2,0) -> Catar | BY9: =VLOOKUP($BX9,$AI$6:$AR$9,10,FALSE) -> -23789500 | CA9: 4 | CB9: =VLOOKUP(CA9,$AH$6:$AI$9,2,0) -> Catar | CC9: =VLOOKUP(CB9,$AI$6:$AR$9,2,FALSE) -> 0 | CD9: =IF(SUM($AK$6:$AK$9)=12,MIN(ABS(BY8-BY9),ABS(BY9-BY10)),100) -> 23789500 | CE9: =VLOOKUP($CB9,$AI$6:$AR$9,9,FALSE) -> -5 | CF9: =VLOOKUP($CB9,$AI$6:$AR$9,7,FALSE) -> 1 | CH9: {=IF($CI$6=$CL$5,$EC$5:$EC$8,IF(OR($CI$6=$CN$5,$CI$6=$CR$5),$EG$5:$EG$6,IF($CI$6=$CP$5,$EF$5:$EF$7,$EL$5)))} -> 4 | CK9: 4 | CL9: {=IF(AND($CC$6:$CC$9=$CC$9,$CD$6:$CD$9<90,$AQ$6:$AQ$9=$AQ$9,$CF$6:$CF$9=$CF$9),1,0)} -> 0 | CM9: {=IF(AND($CC$6:$CC$8=$CC$6,$CD$6:$CD$8<90,$CD$9>90,$CC$6<>$CC$9),1,0)} -> 0 | CN9: {=IF(AND($CC$8:$CC$9=$CC$8,$CD$8:$CD$9<90,$CC$8<>$CC$7),1,0)} -> 0 | CO9: {=IF(AND($CC$9<>$CC$7,$CC$9<>$CC$6),1,0)} -> 1 | CP9: {=IF(AND($CC$7:$CC$9=$CC$7,$CD$7:$CD$9<90,$CC$6<>$CC$9),1,0)} -> 0 | CQ9: {=IF(AND($CC$9<>$CC$7,$CC$9<>$CC$6),1,0)} -> 1 | CR9: {=IF(AND($CC$8:$CC$9=$CC$8,$CD$8:$CD$9<90,$CC$8<>$CC$7),1,0)} -> 0 | CS9: {=IF(AND($CC$9<>$CC$7,$CC$9<>$CC$6),1,0)} -> 1 | CT9: {=IF(AND($CC$6:$CC$9=$CC$6,$CD$6:$CD$9<90,$CE$8:$CE$9=$CE$9,$CE$7<>$CE$9),1,0)} -> 0 | CU9: {=IF(AND($CC$6:$CC$9=$CC$6,$CD$6:$CD$9<90,$CE$6:$CE$9=$CE$6,$CF$8=$CF$9,$CF$7<>$CF$8),1,0)} -> 0 | CV9: {=IF(AND($CC$6:$CC$8=$CC$6,$CD$6:$CD$7<90,$CC$8<>$CC$9),1,0)} -> 0 | CW9: {=IF(AND($CC$7<>$CC$6,$CC$7:$CC$9=$CC$8,$CD$7>90,$CD$8:$CD$9<90),1,0)} -> 0 | CX9: {=IF(AND($CC$7<>$CC$6,$CC$7:$CC$9=$CC$7,$CD$9>90,$CD$7:$CD$8<90),1,0)} -> 0 | CY9: {=IF(AND($CC$9<>$CC$7,$CC$9<>$CC$8),1,0)} -> 1 | CZ9: {=IF(AND($CC$6:$CC$9=$CC$7,$CD$7:$CD$9<90,$CD$6<>$CD$9),1,0)} -> 0 | DA9: {=IF(AND($CC$6:$CC$9=$CC$6,$CD$6:$CD$8<90,$CD$8<>$CD$9),1,0)} -> 0 | DB9: {=IF(AND($CC$6:$CC$9=$CC$9,$CD$6:$CD$7>90,$CD$8:$CD$9<90,$CE$6:$CE$9=$CE$9,$CF$6>$CF$7,$CF$7>$CF$9,$CF$8=$CF$9),1,0)} -> 0 | DC9: {=IF(AND($CC$6:$CC$9=$CC$7,$CD$6>90,$CD$7:$CD$8<90,$CD$9>90,$CE$6:$CE$9=$CE$9,$CF$6>$CF$9,$CF$7=$CF$8,$CF$7>$CF$9),1,0)} -> 0 | DD9: {=IF(AND($CC$6:$CC$9=$CC$9,$CD$6:$CD$7<90,$CD$8:$CD$9>90,$CE$6:$CE$9=$CE$9,$CF$6=$CF$7,$CF$7>$CF$8,$CF$8>$CF$9),1,0)} -> 0 | DE9: {=IF(AND($CC$6:$CC$9=$CC$9,$CD$6:$CD$7>90,$CD$8:$CD$9<90,$CE$6:$CE$9=$CE$9,$CF$6>$CF$9,$CF$7:$CF$9=$CF$9),1,0)} -> 0 | DF9: {=IF(AND($CC$6:$CC$9=$CC$9,$CD$6:$CD$7<90,$CD$8:$CD$9>90,$CE$6:$CE$9=$CE$9,$CF$6:$CF$8=$CF$8,$CF$6:$CF$8>$CF$9),1,0)} -> 0 | DG9: {=IF(AND($CC$6:$CC$9=$CC$9,$CD$6>90,$CD$9>90,$CD$7:$CD$8<90,$CE$6:$CE$9=$CE$9,$CF$6>$CF$7:$CF$9,$CF$7:$CF$9=$CF$9),1,0)} -> 0
AV10: Victorias | AW10: 100 | SWE10: matejero
F11: =F3 -> Fecha | G11: =G3 -> Hora | H11: =H3 -> Jor. | I11: =I3 -> Casa | K11: Gol | L11: Gol | N11: =N3 -> Fuera | AV11: BOMBO | AW11: 1 | CL11: 1 | CM11: 12 | CN11: 18 | CO11: 19 | CP11: 13 | CQ11: 20 | CR11: 21 | CS11: 22 | CT11: 3 | CU11: 2 | CV11: 14 | CW11: 17 | CX11: 16 | CY11: 15 | CZ11: 4 | DA11: 5 | DB11: 10 | DC11: 8 | DD11: 6 | DE11: 11 | DF11: 7 | DG11: 9 | EC11: OP1 | ED11: OP2 | EE11: OP3 | EF11: OP4 | EG11: OP5 | EH11: OP6 | EI11: OP7 | EJ11: OP8 | EK11: OP9 | EL11: OP10
A12: NombreEquipo | B12: B | C12: =COUNTIF(Equipos!$C$2:$C$33,MUNDIAL!B12) -> 4 | E12: B | F12: =Horarios!C12 -> 44886.667 | G12: =Horarios!C12 -> 44886.667 | H12: J1 | I12: =A13 -> Inglaterra | J12: =VLOOKUP(I12,Equipos!$H$2:$I$33,2,0) -> 🏴󠁧󠁢󠁥󠁮󠁧󠁿 | K12: 6 | L12: 2 | M12: =VLOOKUP(N12,Equipos!$H$2:$I$33,2,0) -> 🇮🇷 | N12: =A14 -> Irán | O12: =IF(NOT(OR(ISBLANK(K12),ISBLANK(L12))),1,0) -> 1 | Q12: =CONCATENATE("Grupo"," ",B12) -> Grupo B | AB12: ¡EMPATE! Puedes seleccionar el orden de los empatados. | AH12: =CONCATENATE("Auxiliar - ",Q12) -> Auxiliar - Grupo B | AU12: NR | AY12: =CONCATENATE(Q12," - GOLAVERAGE") -> Grupo B - GOLAVERAGE | BB12: Goles - Partidos Cruzados | BH12: Diferencia de Goles - Partidos Cruzados | BN12: Puntos - Partidos Cruzados | CI12: Valor | CK12: Sum | CL12: =SUM(CL14:CL17) -> 0 | CM12: =SUM(CM14:CM17) -> 0 | CN12: =SUM(CN14:CN17) -> 0 | CO12: =SUM(CO14:CO17) -> 2 | CP12: =SUM(CP14:CP17) -> 0 | CQ12: =SUM(CQ14:CQ17) -> 2 | CR12: =SUM(CR14:CR17) -> 2 | CS12: =SUM(CS14:CS17) -> 4 | ... DG12: =SUM(DG14:DG17) -> 0 | EC12: 1234 | ED12: 123 | EE12: 12 | EF12: 234 | EG12: 34 | EH12: 23 | EI12: 1 | EJ12: 2 | EK12: 3 | EL12: 4
A13: {=IF(ROWS(A$13:A13)<=$C$12,INDEX(INDIRECT(A$12),SMALL(IF(Nivell=$B$12,ROW(Nivell)-ROW(Equipos!$C$2)+1),ROWS(B$12:B12))),"")} -> Inglaterra | F13: =Horarios!C13 -> 44886.917 | G13: =Horarios!C13 -> 44886.917 | H13: J1 | I13: =A15 -> Estados unidos | J13: =VLOOKUP(I13,Equipos!$H$2:$I$33,2,0) -> 🇺🇸 | K13: 1 | L13: 1 | M13: =VLOOKUP(N13,Equipos!$H$2:$I$33,2,0) -> 🏴󠁧󠁢󠁷󠁬󠁳󠁿 | N13: =A16 -> Gales | O13: =IF(NOT(OR(ISBLANK(K13),ISBLANK(L13))),1,0) -> 1 | Q13: Pos | R13: Selección | S13: Pts | T13: J | U13: G | V13: E | W13: P | X13: GF | Y13: GC | Z13: DG | AA13: =COUNTIF(AA14:AA17,"<100") -> 0 | AG13: NR | AH13: Puesto | AI13: Equipo | AJ13: Ptos | AK13: J | AL13: G | AM13: E | AN13: P | AO13: GF | AP13: GC | AQ13: Dif | AR13: Rank | AS13: Puesto | AY13: Equipo | AZ13: NEquipEqual | BA13: PUNTOS | BB13: Ranking Inv | BC13: Entre Iguales | BD13: =AY14 -> Inglaterra | BE13: =AY15 -> Irán | BF13: =AY16 -> Estados unidos | BG13: =AY17 -> Gales | BH13: Ranking Inv | BI13: Entre Iguales | BJ13: =BD13 -> Inglaterra | BK13: =BE13 -> Irán | BL13: =BF13 -> Estados unidos | BM13: =BG13 -> Gales | BN13: Ranking Inv | BO13: Entre Iguales | BP13: =BD13 -> Inglaterra | BQ13: =BE13 -> Irán | BR13: =BF13 -> Estados unidos | BS13: =BG13 -> Gales | BV13: Inicio | BX13: 1R | CB13: Equipo | CC13: Ptos | CD13: Signo | CE13: Dif | CF13: Gf | CK13: Com | CL13: COM_1 | CM13: COM_2 | CN13: COM_3 | CO13: COM_4 | CP13: COM_5 | CQ13: COM_6 | CR13: COM_7 | CS13: COM_8 | CT13: COM_3 | CU13: COM_3 | CV13: COM_4 | CW13: COM_7 | CX13: COM_6 | CY13: COM_6 | CZ13: COM_5 | DA13: COM_2 | DB13: COM_7 | DC13: COM_6 | DD13: COM_4 | DE13: COM_7 | DF13: COM_4 | DG13: COM_6 | EC13: 1 | ED13: 1 | EE13: 1 | EF13: 2 | EG13: 3 | EH13: 2 | EI13: 1 | EJ13: 2 | EK13: 3 | EL13: 4
A14: {=IF(ROWS(A$13:A14)<=$C$12,INDEX(INDIRECT(A$12),SMALL(IF(Nivell=$B$12,ROW(Nivell)-ROW(Equipos!$C$2)+1),ROWS(B$12:B13))),"")} -> Irán | F14: =Horarios!C14 -> 44890.542 | G14: =Horarios!C14 -> 44890.542 | H14: J2 | I14: =A16 -> Gales | J14: =VLOOKUP(I14,Equipos!$H$2:$I$33,2,0) -> 🏴󠁧󠁢󠁷󠁬󠁳󠁿 | K14: 0 | L14: 2 | M14: =VLOOKUP(N14,Equipos!$H$2:$I$33,2,0) -> 🇮🇷 | N14: =A14 -> Irán | O14: =IF(NOT(OR(ISBLANK(K14),ISBLANK(L14))),1,0) -> 1 | Q14: 1 | R14: =VLOOKUP(Q14,$AG$14:$AI$17,3,0) -> Inglaterra | S14: =VLOOKUP(R14,$AI$14:$AR$17,2,FALSE) -> 7 | T14: =VLOOKUP($R14,$AI$14:$AR$17,3,FALSE) -> 3 | U14: =VLOOKUP($R14,$AI$14:$AR$17,4,FALSE) -> 2 | V14: =VLOOKUP($R14,$AI$14:$AR$17,5,FALSE) -> 1 | W14: =VLOOKUP($R14,$AI$14:$AR$17,6,FALSE) -> 0 | X14: =VLOOKUP($R14,$AI$14:$AR$17,7,FALSE) -> 9 | Y14: =VLOOKUP($R14,$AI$14:$AR$17,8,FALSE) -> 2 | Z14: =VLOOKUP($R14,$AI$14:$AR$17,9,FALSE) -> 7 | AA14: =IF(SUM($AK$14:$AK$17)=12,MIN(ABS(BY13-BY14),ABS(BY14-BY15)),100) -> 2.259e+09 | AB14: =IF(AND(AA14>=0,AA14<90),VLOOKUP(Q14,$BU$14:$BV$17,2,0),"") | AF14: =VLOOKUP($R14,$AI$14:$AR$17,10,FALSE) -> 7.8212105e+09 | AG14: =RANK(AU14,$AU$14:$AU$17) -> 1 | AH14: =RANK(AR14,$AR$14:$AR$17) -> 1 | AI14: =A13 -> Inglaterra | AJ14: =AL14*3+AM14*1+AN14*0 -> 7 | AK14: =COUNTIFS($I$4:$I$65,AI14,$K$4:$K$65,"<>",$L$4:$L$65,"<>")+COUNTIFS($N$4:$N$65,AI14,$L$4:$L$65,"<>",$K$4:$K$65,"<>") -> 3 | AL14: {=SUM(($I$4:$I$65=AI14)*($K$4:$K$65<>"")*($L$4:$L$65<>"")*($K$4:$K$65>$L$4:$L$65),($N$4:$N$65=AI14)*($K$4:$K$65<>"")*($L$4:$L$65<>"")*($K$4:$K$65<$L$4:$L$65))} -> 2 | AM14: {=SUM(($I$4:$I$65=AI14)*($K$4:$K$65<>"")*($L$4:$L$65<>"")*($K$4:$K$65=$L$4:$L$65),($N$4:$N$65=AI14)*($K$4:$K$65<>"")*($L$4:$L$65<>"")*($K$4:$K$65=$L$4:$L$65))} -> 1 | AN14: {=SUM(($I$4:$I$65=AI14)*($L$4:$L$65<>"")*($K$4:$K$65<>"")*($K$4:$K$65<$L$4:$L$65),($K$4:$K$65<>"")*($N$4:$N$65=AI14)*($L$4:$L$65<>"")*($K$4:$K$65>$L$4:$L$65))} -> 0 | AO14: {=SUMIFS($K$4:$K$65,$I$4:$I$65,AI14,$K$4:$K$65,"<>",$L$4:$L$65,"<>")+SUMIFS($L$4:$L$65,$N$4:$N$65,AI14,$K$4:$K$65,"<>",$L$4:$L$65,"<>")} -> 9 | AP14: {=SUMIFS($K$4:$K$65,$N$4:$N$65,AI14,$K$4:$K$65,"<>",$L$4:$L$65,"<>")+SUMIFS($L$4:$L$65,$I$4:$I$65,AI14,$K$4:$K$65,"<>",$L$4:$L$65,"<>")} -> 2 | AQ14: =AO14-AP14 -> 7 | AR14: =IF(AK14=0,-($AW$11*VLOOKUP(AI14,Tabla3[[NombreEquipo]:[Rank]],3,FALSE)),AJ14*$AW$4+AQ14*$AW$5+AO14*$AW$6+BA14-($AW$11*VLOOKUP(AI14,Tabla3[[NombreEquipo]:[Rank]],3,FALSE)/100)) -> 7.8212105e+09 | AS14: =AH14 -> 1 | AU14: =IFERROR(AR14-VLOOKUP(AI14,$AB$14:$AC$17,2,0),AR14) -> 7.8212105e+09 | AY14: =AI14 -> Inglaterra | AZ14: =COUNTIF(AJ14:AJ17,AJ14) -> 1 | BA14: =(BB14*$AW$9)+(BH14*$AW$8)+(BN14*$AW$7) -> 210500 | BB14: =RANK(BC14,BC14:BC17,1) -> 1 | BC14: =SUM(IF(AND(AJ14=AJ15,AQ14=AQ15,AO14=AO15),BE14,0),IF(AND(AJ14=AJ16,AQ14=AQ16,AO14=AO16),BF14,0),IF(AND(AJ14=AJ17,AQ14=AQ17,AO14=AO17),BG14,0)) -> 0 | BD14: 0 | BE14: {=SUMIFS($K$12:$K$17,$I$12:$I$17,$AY14,$K$12:$K$17,"<>",$L$12:$L$17,"<>",$N$12:$N$17,BE13)+SUMIFS($L$12:$L$17,$I$12:$I$17,BE13,$K$12:$K$17,"<>",$L$12:$L$17,"<>",$N$12:$N$17,$AY14)} -> 6 | BF14: {=SUMIFS($K$12:$K$17,$I$12:$I$17,$AY14,$K$12:$K$17,"<>",$L$12:$L$17,"<>",$N$12:$N$17,BF13)+SUMIFS($L$12:$L$17,$I$12:$I$17,BF13,$K$12:$K$17,"<>",$L$12:$L$17,"<>",$N$12:$N$17,$AY14)} -> 0 | BG14: {=SUMIFS($K$12:$K$17,$I$12:$I$17,$AY14,$K$12:$K$17,"<>",$L$12:$L$17,"<>",$N$12:$N$17,BG13)+SUMIFS($L$12:$L$17,$I$12:$I$17,BG13,$K$12:$K$17,"<>",$L$12:$L$17,"<>",$N$12:$N$17,$AY14)} -> 3 | BH14: =RANK(BI14,BI14:BI17,1) -> 1 | BI14: =SUM(IF(AND(AJ14=AJ15,AQ14=AQ15,AO14=AO15),BK14,0),IF(AND(AJ14=AJ16,AQ14=AQ16,AO14=AO16),BL14,0),IF(AND(AJ14=AJ17,AQ14=AQ17,AO14=AO17),BM14,0)) -> 0 | BJ14: 0 | BK14: =BE14-BD15 -> 4 | BL14: =BF14-BD16 -> 0 | BM14: =BG14-BD17 -> 3 | BN14: =RANK(BO14,BO14:BO17,1) -> 1 | BO14: =SUM(IF(AND(AJ14=AJ15,AQ14=AQ15,AO14=AO15),BQ14,0),IF(AND(AJ14=AJ16,AQ14=AQ16,AO14=AO16),BR14,0),IF(AND(AJ14=AJ17,AQ14=AQ17,AO14=AO17),BS14,0)) -> 0 | BP14: 0 | BQ14: {=SUM((I$4:I$49=AY14)*(N$4:N$49=BQ13)*(K$4:K$49<>"")*(L$4:L$49<>"")*(K$4:K$49>L$4:L$49)*3,(N$4:N$49=AY14)*(I$4:I$49=BQ13)*(K$4:K$49<>"")*(L$4:L$49<>"")*(K$4:K$49=L$4:L$49)*1,(N$4:N$49=AY14)*(I$4:I$49=BQ13)*(K$4:K$49<>"")*(L$4:L$49<>"")*(K$4:K$49<L$4:L$49)*3,(I$4:I$49=AY14)*(N$4:N$49=BQ13)*(K$4:K$49<>"")*(L$4:L$49<>"")*(K$4:K$49=L$4:L$49)*1)} -> 3 | BR14: {=SUM((I$4:I$49=AY14)*(N$4:N$49=BR13)*(K$4:K$49<>"")*(L$4:L$49<>"")*(K$4:K$49>L$4:L$49)*3,(N$4:N$49=AY14)*(I$4:I$49=BR13)*(K$4:K$49<>"")*(L$4:L$49<>"")*(K$4:K$49=L$4:L$49)*1,(N$4:N$49=AY14)*(I$4:I$49=BR13)*(K$4:K$49<>"")*(L$4:L$49<>"")*(K$4:K$49<L$4:L$49)*3,(I$4:I$49=AY14)*(N$4:N$49=BR13)*(K$4:K$49<>"")*(L$4:L$49<>"")*(K$4:K$49=L$4:L$49)*1)} -> 1 | BS14: {=SUM((I$4:I$49=AY14)*(N$4:N$49=BS13)*(K$4:K$49<>"")*(L$4:L$49<>"")*(K$4:K$49>L$4:L$49)*3,(N$4:N$49=AY14)*(I$4:I$49=BS13)*(K$4:K$49<>"")*(L$4:L$49<>"")*(K$4:K$49=L$4:L$49)*1,(N$4:N$49=AY14)*(I$4:I$49=BS13)*(K$4:K$49<>"")*(L$4:L$49<>"")*(K$4:K$49<L$4:L$49)*3,(I$4:I$49=AY14)*(N$4:N$49=BS13)*(K$4:K$49<>"")*(L$4:L$49<>"")*(K$4:K$49=L$4:L$49)*1)} -> 3 | BT14: 1 | BU14: =RANK(BW14,$BW$14:$BW$17) -> 1 | BV14: =A13 -> Inglaterra | BW14: =AR14 -> 7.8212105e+09 | BX14: =VLOOKUP(Q14,$AH$14:$AI$17,2,0) -> Inglaterra | BY14: =VLOOKUP($BX14,$AI$14:$AR$17,10,FALSE) -> 7.8212105e+09 | CA14: 1 | CB14: =VLOOKUP(CA14,$AH$14:$AI$17,2,0) -> Inglaterra | CC14: =VLOOKUP(CB14,$AI$14:$AR$17,2,FALSE) -> 7 | CD14: =IF(SUM($AK$14:$AK$17)=12,MIN(ABS(BY13-BY14),ABS(BY14-BY15)),100) -> 2.259e+09 | CE14: =VLOOKUP($CB14,$AI$14:$AR$17,9,FALSE) -> 7 | CF14: =VLOOKUP($CB14,$AI$14:$AR$17,7,FALSE) -> 9 | CH14: {=IF($CI$14=$CL$13,$EC$13:$EC$16,IF($CI$14=$CM$13,$ED$13:$ED$15,IF(OR($CI$14=$CN$13,$CI$14=$CO$13),$EE$13:$EE$14,$EI$13)))} -> 1 | CI14: =IFERROR(HLOOKUP(4,CL12:DI13,2,0),CS13) -> COM_8 | CK14: 1 | CL14: {=IF(AND($CC$14:$CC$17=$CC$14,$CD$14:$CD$17<90,$AQ$14:$AQ$17=$AQ$14,$CF$14:$CF$17=$CF$14),1,0)} -> 0 | CM14: {=IF(AND($CC$14:$CC$16=$CC$14,$CD$14:$CD$16<90,$CC$14<>$CC$17),1,0)} -> 0 | CN14: {=IF(AND($CC$14:$CC$15=$CC$14,$CD$14:$CD$15<90,$CC$14<>$CC$16),1,0)} -> 0 | CO14: {=IF(AND($CC$14:$CC$15=$CC$14,$CD$14:$CD$15<90,$CC$14<>$CC$16),1,0)} -> 0 | CP14: {=IF(AND($CC$15:$CC$17=$CC$15,$CD$15:$CD$17<90,$CC$14<>$CC$15),1,0)} -> 0 | CQ14: {=IF(AND($CC$14<>$CC$15,$CC$14<>$CC$17),1,0)} -> 1 | CR14: {=IF(AND($CC$14<>$CC$15,$CC$14<>$CC$17),1,0)} -> 1 | CS14: {=IF(AND($CC$14<>$CC$15,$CC$14<>$CC$17),1,0)} -> 1 | CT14: {=IF(AND($CC$14:$CC$17=$CC$14,$CD$14:$CD$17<90,$CE$14:$CE$15=$CE$14,$CE$14<>$CE$16),1,0)} -> 0 | CU14: {=IF(AND($CC$14:$CC$17=$CC$14,$CD$14:$CD$17<90,$CE$14:$CE$17=$CE$14,$CF$14=$CF$15,$CF$14<>$CF$16),1,0)} -> 0 | CV14: {=IF(AND($CC$14:$CC$16=$CC$14,$CD$14:$CD$15<90,$CD$16>90),1,0)} -> 0 | CW14: {=IF(AND($CC$14<>$CC$15,$CC$14<>$CC$16),1,0)} -> 1 | CX14: {=IF(AND($CC$14<>$CC$15,$CC$14<>$CC$16),1,0)} -> 1 | CY14: {=IF(AND($CC$14<>$CC$17,$CC$14:$CC$16=$CC$14,$CD$14>90,$CD$15:$CD$16<90),1,0)} -> 0 | CZ14: {=IF(AND($CC$14:$CC$17=$CC$14,$CD$15:$CD$17<90,$CD$14<>$CD$15),1,0)} -> 0 | DA14: {=IF(AND($CC$14:$CC$17=$CC$14,$CD$14:$CD$16<90,$CD$14<>$CD$17),1,0)} -> 0 | DB14: {=IF(AND($CC$14:$CC$17=$CC$14,$CD$14:$CD$15>90,$CD$16:$CD$17<90,$CE$14:$CE$17=$CE$14,$CF$14>$CF$15,$CF$14>$CF$16,$CF$14>$CF$17),1,0)} -> 0 | DC14: {=IF(AND($CC$14:$CC$17=$CC$14,$CD$14>90,$CD$15:$CD$16<90,$CD$17>90,$CE$14:$CE$17=$CE$14,$CF$14>$CF$15,$CF$14>$CF$16,$CF$14>$CF$17),1,0)} -> 0 | DD14: {=IF(AND($CC$14:$CC$17=$CC$14,$CD$14:$CD$15<90,$CD$16:$CD$17>90,$CE$14:$CE$17=$CE$14,$CF$14=$CF$15,$CF$14>$CF$16,$CF$14>$CF$17),1,0)} -> 0 | DE14: {=IF(AND($CC$14:$CC$17=$CC$14,$CD$14:$CD$15>90,$CD$16:$CD$17<90,$CE$14:$CE$17=$CE$14,$CF$14>$CF$15,$CF$15:$CF$17=$CF$15),1,0)} -> 0 | DF14: {=IF(AND($CC$14:$CC$17=$CC$14,$CD$14:$CD$15<90,$CD$16:$CD$17>90,$CE$14:$CE$17=$CE$14,$CF$14:$CF$16=$CF$14,$CF$14>$CF$17),1,0)} -> 0 | DG14: {=IF(AND($CC$14:$CC$17=$CC$14,$CD$14>90,$CD$17>90,$CD$15:$CD$16<90,$CE$14:$CE$17=$CE$14,$CF$14>$CF$15:$CF$17),1,0)} -> 0 | EC14: 2 | ED14: 2 | EE14: 2 | EF14: 3 | EG14: 4 | EH14: 3 | HJU14: matejero
A15: {=IF(ROWS(A$13:A15)<=$C$12,INDEX(INDIRECT(A$12),SMALL(IF(Nivell=$B$12,ROW(Nivell)-ROW(Equipos!$C$2)+1),ROWS(B$12:B14))),"")} -> Estados unidos | F15: =Horarios!C15 -> 44890.917 | G15: =Horarios!C15 -> 44890.917 | H15: J2 | I15: =A13 -> Inglaterra | J15: =VLOOKUP(I15,Equipos!$H$2:$I$33,2,0) -> 🏴󠁧󠁢󠁥󠁮󠁧󠁿 | K15: 0 | L15: 0 | M15: =VLOOKUP(N15,Equipos!$H$2:$I$33,2,0) -> 🇺🇸 | N15: =A15 -> Estados unidos | O15: =IF(NOT(OR(ISBLANK(K15),ISBLANK(L15))),1,0) -> 1 | Q15: 2 | R15: =VLOOKUP(Q15,$AG$14:$AI$17,3,0) -> Estados unidos | S15: =VLOOKUP(R15,$AI$14:$AR$17,2,FALSE) -> 5 | T15: =VLOOKUP($R15,$AI$14:$AR$17,3,FALSE) -> 3 | U15: =VLOOKUP($R15,$AI$14:$AR$17,4,FALSE) -> 1 | V15: =VLOOKUP($R15,$AI$14:$AR$17,5,FALSE) -> 2 | W15: =VLOOKUP($R15,$AI$14:$AR$17,6,FALSE) -> 0 | X15: =VLOOKUP($R15,$AI$14:$AR$17,7,FALSE) -> 2 | Y15: =VLOOKUP($R15,$AI$14:$AR$17,8,FALSE) -> 1 | Z15: =VLOOKUP($R15,$AI$14:$AR$17,9,FALSE) -> 1 | AA15: =IF(SUM($AK$14:$AK$17)=12,MIN(ABS(BY14-BY15),ABS(BY15-BY16)),100) -> 2.24e+09 | AB15: =IF(AND(AA15>=0,AA15<90),VLOOKUP(Q15,$BU$14:$BV$17,2,0),"") | AF15: =VLOOKUP($R15,$AI$14:$AR$17,10,FALSE) -> 5.5622105e+09 | AG15: =RANK(AU15,$AU$14:$AU$17) -> 3 | AH15: =RANK(AR15,$AR$14:$AR$17) -> 3 | AI15: =A14 -> Irán | AJ15: =AL15*3+AM15*1+AN15*0 -> 3 | AK15: =COUNTIFS($I$4:$I$65,AI15,$K$4:$K$65,"<>",$L$4:$L$65,"<>")+COUNTIFS($N$4:$N$65,AI15,$L$4:$L$65,"<>",$K$4:$K$65,"<>") -> 3 | AL15: {=SUM(($I$4:$I$65=AI15)*($K$4:$K$65<>"")*($L$4:$L$65<>"")*($K$4:$K$65>$L$4:$L$65),($N$4:$N$65=AI15)*($K$4:$K$65<>"")*($L$4:$L$65<>"")*($K$4:$K$65<$L$4:$L$65))} -> 1 | AM15: {=SUM(($I$4:$I$65=AI15)*($K$4:$K$65<>"")*($L$4:$L$65<>"")*($K$4:$K$65=$L$4:$L$65),($N$4:$N$65=AI15)*($K$4:$K$65<>"")*($L$4:$L$65<>"")*($K$4:$K$65=$L$4:$L$65))} -> 0 | AN15: {=SUM(($I$4:$I$65=AI15)*($L$4:$L$65<>"")*($K$4:$K$65<>"")*($K$4:$K$65<$L$4:$L$65),($K$4:$K$65<>"")*($N$4:$N$65=AI15)*($L$4:$L$65<>"")*($K$4:$K$65>$L$4:$L$65))} -> 2 | AO15: {=SUMIFS($K$4:$K$65,$I$4:$I$65,AI15,$K$4:$K$65,"<>",$L$4:$L$65,"<>")+SUMIFS($L$4:$L$65,$N$4:$N$65,AI15,$K$4:$K$65,"<>",$L$4:$L$65,"<>")} -> 4 | AP15: {=SUMIFS($K$4:$K$65,$N$4:$N$65,AI15,$K$4:$K$65,"<>",$L$4:$L$65,"<>")+SUMIFS($L$4:$L$65,$I$4:$I$65,AI15,$K$4:$K$65,"<>",$L$4:$L$65,"<>")} -> 7 | AQ15: =AO15-AP15 -> -3 | AR15: =IF(AK15=0,-($AW$11*VLOOKUP(AI15,Tabla3[[NombreEquipo]:[Rank]],3,FALSE)),AJ15*$AW$4+AQ15*$AW$5+AO15*$AW$6+BA15-($AW$11*VLOOKUP(AI15,Tabla3[[NombreEquipo]:[Rank]],3,FALSE)/100)) -> 3.3222105e+09 | AS15: =AH15 -> 3 | AU15: =IFERROR(AR15-VLOOKUP(AI15,$AB$14:$AC$17,2,0),AR15) -> 3.3222105e+09 | AY15: =AI15 -> Irán | AZ15: =COUNTIF(AJ14:AJ17,AJ15) -> 1 | BA15: =(BB15*$AW$9)+(BH15*$AW$8)+(BN15*$AW$7) -> 210500 | BB15: =RANK(BC15,BC14:BC17,1) -> 1 | BC15: =SUM(IF(AND(AJ15=AJ16,AQ15=AQ16,AO15=AO16),BF15,0),IF(AND(AJ15=AJ17,AQ15=AQ17,AO15=AO17),BG15,0),IF(AND(AJ15=AJ14,AQ15=AQ14,AO15=AO14),BD15,0)) -> 0 | BD15: {=SUMIFS($K$12:$K$17,$I$12:$I$17,$AY15,$K$12:$K$17,"<>",$L$12:$L$17,"<>",$N$12:$N$17,BD13)+SUMIFS($L$12:$L$17,$I$12:$I$17,BD13,$K$12:$K$17,"<>",$L$12:$L$17,"<>",$N$12:$N$17,$AY15)} -> 2 | BE15: 0 | BF15: {=SUMIFS($K$12:$K$17,$I$12:$I$17,$AY15,$K$12:$K$17,"<>",$L$12:$L$17,"<>",$N$12:$N$17,BF13)+SUMIFS($L$12:$L$17,$I$12:$I$17,BF13,$K$12:$K$17,"<>",$L$12:$L$17,"<>",$N$12:$N$17,$AY15)} -> 0 | BG15: {=SUMIFS($K$12:$K$17,$I$12:$I$17,$AY15,$K$12:$K$17,"<>",$L$12:$L$17,"<>",$N$12:$N$17,BG13)+SUMIFS($L$12:$L$17,$I$12:$I$17,BG13,$K$12:$K$17,"<>",$L$12:$L$17,"<>",$N$12:$N$17,$AY15)} -> 2 | BH15: =RANK(BI15,BI14:BI17,1) -> 1 | BI15: =SUM(IF(AND(AJ15=AJ16,AQ15=AQ16,AO15=AO16),BL15,0),IF(AND(AJ15=AJ17,AQ15=AQ17,AO15=AO17),BM15,0),IF(AND(AJ15=AJ14,AQ15=AQ14,AO15=AO14),BJ15,0)) -> 0 | BJ15: =BD15-BE14 -> -4 | BK15: 0 | BL15: =BF15-BE16 -> -1 | BM15: =BG15-BE17 -> 2 | BN15: =RANK(BO15,BO14:BO17,1) -> 1 | BO15: =SUM(IF(AND(AJ15=AJ16,AQ15=AQ16,AO15=AO16),BR15,0),IF(AND(AJ15=AJ17,AQ15=AQ17,AO15=AO17),BS15,0),IF(AND(AJ15=AJ14,AQ15=AQ14,AO15=AO14),BP15,0)) -> 0 | BP15: {=SUM((I$4:I$49=AY15)*(N$4:N$49=BP13)*(K$4:K$49<>"")*(L$4:L$49<>"")*(K$4:K$49>L$4:L$49)*3,(N$4:N$49=AY15)*(I$4:I$49=BP13)*(K$4:K$49<>"")*(L$4:L$49<>"")*(K$4:K$49=L$4:L$49)*1,(N$4:N$49=AY15)*(I$4:I$49=BP13)*(K$4:K$49<>"")*(L$4:L$49<>"")*(K$4:K$49<L$4:L$49)*3,(I$4:I$49=AY15)*(N$4:N$49=BP13)*(K$4:K$49<>"")*(L$4:L$49<>"")*(K$4:K$49=L$4:L$49)*1)} -> 0 | BQ15: 0 | BR15: {=SUM((I$4:I$49=AY15)*(N$4:N$49=BR13)*(K$4:K$49<>"")*(L$4:L$49<>"")*(K$4:K$49>L$4:L$49)*3,(N$4:N$49=AY15)*(I$4:I$49=BR13)*(K$4:K$49<>"")*(L$4:L$49<>"")*(K$4:K$49=L$4:L$49)*1,(N$4:N$49=AY15)*(I$4:I$49=BR13)*(K$4:K$49<>"")*(L$4:L$49<>"")*(K$4:K$49<L$4:L$49)*3,(I$4:I$49=AY15)*(N$4:N$49=BR13)*(K$4:K$49<>"")*(L$4:L$49<>"")*(K$4:K$49=L$4:L$49)*1)} -> 0 | BS15: {=SUM((I$4:I$49=AY15)*(N$4:N$49=BS13)*(K$4:K$49<>"")*(L$4:L$49<>"")*(K$4:K$49>L$4:L$49)*3,(N$4:N$49=AY15)*(I$4:I$49=BS13)*(K$4:K$49<>"")*(L$4:L$49<>"")*(K$4:K$49=L$4:L$49)*1,(N$4:N$49=AY15)*(I$4:I$49=BS13)*(K$4:K$49<>"")*(L$4:L$49<>"")*(K$4:K$49<L$4:L$49)*3,(I$4:I$49=AY15)*(N$4:N$49=BS13)*(K$4:K$49<>"")*(L$4:L$49<>"")*(K$4:K$49=L$4:L$49)*1)} -> 3 | BT15: 2 | BU15: =RANK(BW15,$BW$14:$BW$17) -> 3 | BV15: =A14 -> Irán | BW15: =AR15 -> 3.3222105e+09 | BX15: =VLOOKUP(Q15,$AH$14:$AI$17,2,0) -> Estados unidos | BY15: =VLOOKUP($BX15,$AI$14:$AR$17,10,FALSE) -> 5.5622105e+09 | CA15: 2 | CB15: =VLOOKUP(CA15,$AH$14:$AI$17,2,0) -> Estados unidos | CC15: =VLOOKUP(CB15,$AI$14:$AR$17,2,FALSE) -> 5 | CD15: =IF(SUM($AK$14:$AK$17)=12,MIN(ABS(BY14-BY15),ABS(BY15-BY16)),100) -> 2.24e+09 | CE15: =VLOOKUP($CB15,$AI$14:$AR$17,9,FALSE) -> 1 | CF15: =VLOOKUP($CB15,$AI$14:$AR$17,7,FALSE) -> 2 | CH15: {=IF($CI$14=$CL$13,$EC$13:$EC$16,IF($CI$14=$CM$13,$ED$13:$ED$15,IF(OR($CI$14=$CN$13,$CI$14=$CO$13),$EE$13:$EE$14,IF($CI$14=$CP$13,$EF$13:$EF$15,(IF($CI$14=$CQ$13,$EH$13:$EH$14,$EJ$13))))))} -> 2 | CK15: 2 | CL15: {=IF(AND($CC$14:$CC$17=$CC$15,$CD$14:$CD$17<90,$AQ$14:$AQ$17=$AQ$15,$CF$14:$CF$17=$CF$15),1,0)} -> 0 | CM15: {=IF(AND($CC$14:$CC$16=$CC$15,$CD$14:$CD$16<90,$CC$15<>$CC$17),1,0)} -> 0 | CN15: {=IF(AND($CC$14:$CC$15=$CC$14,$CD$14:$CD$15<90,$CC$14<>$CC$16),1,0)} -> 0 | CO15: {=IF(AND($CC$14:$CC$15=$CC$14,$CD$14:$CD$15<90,$CC$14<>$CC$16),1,0)} -> 0 | CP15: {=IF(AND($CC$15:$CC$17=$CC$15,$CD$15:$CD$17<90,$CC$14<>$CC$15),1,0)} -> 0 | CQ15: {=IF(AND($CC$15:$CC$16=$CC$15,$CD$15:$CD$16<90,$CC$15<>$CC$14,$CC$15<>$CC$17),1,0)} -> 0 | CR15: {=IF(AND($CC$15<>$CC$14,$CC$15<>$CC$16),1,0)} -> 1 | CS15: {=IF(AND($CC$15<>$CC$14,$CC$15<>$CC$16),1,0)} -> 1 | CT15: {=IF(AND($CC$14:$CC$17=$CC$14,$CD$14:$CD$17<90,$CE$14:$CE$15=$CE$14,$CE$15<>$CE$16),1,0)} -> 0 | CU15: {=IF(AND($CC$14:$CC$17=$CC$14,$CD$14:$CD$17<90,$CE$14:$CE$17=$CE$14,$CF$14=$CF$15,$CF$15<>$CF$16),1,0)} -> 0 | CV15: {=IF(AND($CC$14:$CC$16=$CC$15,$CD$14:$CD$15<90,$CD$16>90),1,0)} -> 0 | CW15: {=IF(AND($CC$15<>$CC$14,$CC$15:$CC$17=$CC$15,$CD$15>90,$CD$16:$CD$17<90),1,0)} -> 0 | CX15: {=IF(AND($CC$15<>$CC$14,$CC$15:$CC$17=$CC$15,$CD$17>90,$CD$15:$CD$16<90),1,0)} -> 0 | CY15: {=IF(AND($CC$15<>$CC$17,$CC$14:$CC$16=$CC$15,$CD$14>90,$CD$15:$CD$16<90),1,0)} -> 0 | CZ15: {=IF(AND($CC$14:$CC$17=$CC$15,$CD$15:$CD$17<90,$CD$14<>$CD$15),1,0)} -> 0 | DA15: {=IF(AND($CC$14:$CC$17=$CC$15,$CD$14:$CD$16<90,$CD$15<>$CD$17),1,0)} -> 0 | DB15: {=IF(AND($CC$14:$CC$17=$CC$15,$CD$14:$CD$15>90,$CD$16:$CD$17<90,$CE$14:$CE$17=$CE$15,$CF$14>$CF$15,$CF$15>$CF$16,$CF$15>$CF$17),1,0)} -> 0 | DC15: {=IF(AND($CC$14:$CC$17=$CC$15,$CD$14>90,$CD$15:$CD$16<90,$CD$17>90,$CE$14:$CE$17=$CE$15,$CF$14>$CF$15,$CF$15=$CF$16,$CF$15>$CF$17),1,0)} -> 0 | DD15: {=IF(AND($CC$14:$CC$17=$CC$15,$CD$14:$CD$15<90,$CD$16:$CD$17>90,$CE$14:$CE$17=$CE$15,$CF$14=$CF$15,$CF$15>$CF$16,$CF$15>$CF$17),1,0)} -> 0 | DE15: {=IF(AND($CC$14:$CC$17=$CC$15,$CD$14:$CD$15>90,$CD$16:$CD$17<90,$CE$14:$CE$17=$CE$15,$CF$14>$CF$15,$CF$15:$CF$17=$CF$15),1,0)} -> 0 | DF15: {=IF(AND($CC$14:$CC$17=$CC$15,$CD$14:$CD$15<90,$CD$16:$CD$17>90,$CE$14:$CE$17=$CE$15,$CF$14:$CF$16=$CF$15,$CF$15>$CF$17),1,0)} -> 0 | DG15: {=IF(AND($CC$14:$CC$17=$CC$15,$CD$14>90,$CD$17>90,$CD$15:$CD$16<90,$CE$14:$CE$17=$CE$15,$CF$14>$CF$15:$CF$17,$CF$15:$CF$17=$CF$15),1,0)} -> 0 | EC15: 3 | ED15: 3 | EF15: 4
